Workbook

Sheet Top WS
J1: =$H$4+($H$4*J3) -> 3600 | K1: =$H$4+($H$4*K3) -> 3800
J2: 4000 | K2: 4000 | L2: =$H$4+($H$4*L3) -> 4000 | M2: =$H$4+($H$4*M3) -> 4120 | N2: =$H$4+($H$4*N3) -> 4320 | O2: =$H$4+($H$4*O3) -> 4400 | P2: =$H$4+($H$4*P3) -> 4600 | Q2: =$H$4+($H$4*Q3) -> 4800 | R2: =$H$4+($H$4*R3) -> 5200
D3: Incentive base | I3: Money | J3: -0.1 | K3: -0.05 | L3: 0 | M3: 0.03 | N3: 0.08 | O3: 0.1 | P3: 0.15 | Q3: 0.2 | R3: 0.3 | U3: Simulation
C4: Depot | D4: Now | E4: New | G4: Incentive $ | H4: 4000 | I4: GOAL | J4: 0.9 | K4: 0.95 | L4: 1 | M4: 1.03 | N4: 1.06 | O4: 1.1 | P4: 1.15 | Q4: 1.2 | R4: 1.3 | W4: 45566 | X4: 45597 | Y4: 45627 | Z4: Total
C5: Area Manger | D5: 5000 | E5: 5000 | U5: Real | V5: Sales (1-2-3-4) | W5: 5000 | X5: 5000 | Y5: 5000 | Z5: =SUM(W5:Y5) -> 15000
C6: Depocho | D6: 4000 | E6: 4000 | G6: G1(CORE) | H6: 0.05 | I6: AJINOMOTO | J6: =H6*$J$2 -> 200 | K6: =H6*$K$2 -> 200 | L6: =H6*$L$2 -> 200 | M6: =H6*$M$2 -> 206 | N6: =H6*$N$2 -> 216 | O6: =H6*$O$2 -> 220 | P6: =H6*$P$2 -> 230 | Q6: =H6*$Q$2 -> 240 | R6: =H6*$R$2 -> 260
C7: D.Depocho | D7: 4000 | E7: 4000 | H7: 0.1 | I7: ROSDEE | J7: =H7*$J$2 -> 400 | K7: =H7*$K$2 -> 400 | L7: =H7*$L$2 -> 400 | M7: =H7*$M$2 -> 412 | N7: =H7*$N$2 -> 432 | O7: =H7*$O$2 -> 440 | P7: =H7*$P$2 -> 460 | Q7: =H7*$Q$2 -> 480 | R7: =H7*$R$2 -> 520 | U7: New Metod | V7: Sales 1 | W7: 6000 | X7: 5000 | Y7: 4500 | Z7: =SUM(W7:Y7) -> 15500
C8: CV | D8: 2500 | E8: 2500 | H8: 0.2 | I8: BIRDY | J8: =H8*$J$2 -> 800 | K8: =H8*$K$2 -> 800 | L8: =H8*$L$2 -> 800 | M8: =H8*$M$2 -> 824 | N8: =H8*$N$2 -> 864 | O8: =H8*$O$2 -> 880 | P8: =H8*$P$2 -> 920 | Q8: =H8*$Q$2 -> 960 | R8: =H8*$R$2 -> 1040 | V8: Sales 2 | W8: =I39 -> 1244 | X8: 5200 | Y8: 5000 | Z8: =SUM(W8:Y8) -> 11444
C9: Driver | D9: 1200 | E9: 1200 | V9: Sales3 | W9: 5000 | X9: 4900 | Y9: 6500 | Z9: =SUM(W9:Y9) -> 16400 | AA9: =Z9/Z5 -> 1.0933333
C10: CVFV | E10: 2500 | G10: G2(GD) | H10: 0.05 | I10: AJI-PLUS | J10: =H10*$J$2 -> 200 | K10: =H10*$K$2 -> 200 | L10: =H10*$L$2 -> 200 | M10: =H10*$M$2 -> 206 | N10: =H10*$N$2 -> 216 | O10: =H10*$O$2 -> 220 | P10: =H10*$P$2 -> 230 | Q10: =H10*$Q$2 -> 240 | R10: =H10*$R$2 -> 260 | V10: Sales 4 | W10: 4800 | X10: 4000 | Y10: 5000 | Z10: =SUM(W10:Y10) -> 13800
C11: WSF | E11: 3500 | H11: 0.1 | I11: ROSDEE CUBE | J11: =H11*$J$2 -> 400 | K11: =H11*$K$2 -> 400 | L11: =H11*$L$2 -> 400 | M11: =H11*$M$2 -> 412 | N11: =H11*$N$2 -> 432 | O11: =H11*$O$2 -> 440 | P11: =H11*$P$2 -> 460 | Q11: =H11*$Q$2 -> 480 | R11: =H11*$R$2 -> 520 | Y11: Average | Z11: =MEDIAN(Z7:Z10) -> 14650 | AA11: =Z11/Z5-1 -> -0.023333333
C12: WH | E12: 3500 | H12: 0.05 | I12: ROSDEE MENU | J12: =H12*$J$2 -> 200 | K12: =H12*$K$2 -> 200 | L12: =H12*$L$2 -> 200 | M12: =H12*$M$2 -> 206 | N12: =H12*$N$2 -> 216 | O12: =H12*$O$2 -> 220 | P12: =H12*$P$2 -> 230 | Q12: =H12*$Q$2 -> 240 | R12: =H12*$R$2 -> 260
H13: 0.1 | I13: ROSDEE NOODLE | J13: =H13*$J$2 -> 400 | K13: =H13*$K$2 -> 400 | L13: =H13*$L$2 -> 400 | M13: =H13*$M$2 -> 412 | N13: =H13*$N$2 -> 432 | O13: =H13*$O$2 -> 440 | P13: =H13*$P$2 -> 460 | Q13: =H13*$Q$2 -> 480 | R13: =H13*$R$2 -> 520
J14: =H14*$J$2 -> 0 | K14: =H14*$K$2 -> 0 | L14: =H14*$L$2 -> 0 | M14: =H14*$M$2 -> 0 | N14: =H14*$N$2 -> 0 | O14: =H14*$O$2 -> 0 | P14: =H14*$P$2 -> 0 | Q14: =H14*$Q$2 -> 0 | R14: =H14*$R$2 -> 0
G16: G3(BB) | H16: 0.15 | I16: YUMYUM | J16: =H16*$J$2 -> 600 | K16: =H16*$K$2 -> 600 | L16: =H16*$L$2 -> 600 | M16: =H16*$M$2 -> 618 | N16: =H16*$N$2 -> 648 | O16: =H16*$O$2 -> 660 | P16: =H16*$P$2 -> 690 | Q16: =H16*$Q$2 -> 720 | R16: =H16*$R$2 -> 780 | U16: Cascade concept
H17: 0.1 | I17: POWDER COFFEE | J17: =H17*$J$2 -> 400 | K17: =H17*$K$2 -> 400 | L17: =H17*$L$2 -> 400 | M17: =H17*$M$2 -> 412 | N17: =H17*$N$2 -> 432 | O17: =H17*$O$2 -> 440 | P17: =H17*$P$2 -> 460 | Q17: =H17*$Q$2 -> 480 | R17: =H17*$R$2 -> 520
U18: Salesman | V18: Incentive
B19: AJINOMOTO | C19: ROSDEE | D19: BIRDY | E19: AJI Plus | G19: Others | H19: 0.05 | I19: Takumi-Aji | J19: =H19*$J$2 -> 200 | K19: =H19*$K$2 -> 200 | L19: =H19*$L$2 -> 200 | M19: =H19*$M$2 -> 206 | N19: =H19*$N$2 -> 216 | O19: =H19*$O$2 -> 220 | P19: =H19*$P$2 -> 230 | Q19: =H19*$Q$2 -> 240 | R19: =H19*$R$2 -> 260
A20: 0 | B20: =J10 -> 200 | C20: =J11 -> 400 | D20: =J12 -> 200 | E20: =J13 -> 400 | H20: 0.05 | I20: ROSDEE MENU KKR | J20: =H20*$J$2 -> 200 | K20: =H20*$K$2 -> 200 | L20: =H20*$L$2 -> 200 | M20: =H20*$M$2 -> 206 | N20: =H20*$N$2 -> 216 | O20: =H20*$O$2 -> 220 | P20: =H20*$P$2 -> 230 | Q20: =H20*$Q$2 -> 240 | R20: =H20*$R$2 -> 260 | U20: All Depot Salesman | V20: Depocho | W20: incentive
A21: 0.90001 | B21: =K10 -> 200 | C21: =K11 -> 400 | D21: =K12 -> 200 | E21: =K13 -> 400
A22: 0.95001 | B22: =L10 -> 200 | C22: =L11 -> 400 | D22: =L12 -> 200 | E22: =L13 -> 400 | U22: All Area depot result | V22: Area Manager | W22: Incentive
A23: 1.00001 | B23: =M10 -> 206 | C23: =M11 -> 412 | D23: =M12 -> 206 | E23: =M13 -> 412
A24: 1.03001 | B24: =N10 -> 216 | C24: =N11 -> 432 | D24: =N12 -> 216 | E24: =N13 -> 432 | U24: All Area manager Result | V24: Division manager | W24: Incetive
A25: =106.001% -> 1.06001 | B25: =O10 -> 220 | C25: =O11 -> 440 | D25: =O12 -> 220 | E25: =O13 -> 440
A26: =110.001% -> 1.10001 | B26: =P10 -> 230 | C26: =P11 -> 460 | D26: =P12 -> 230 | E26: =P13 -> 460
A27: =115.001% -> 1.15001 | B27: =Q10 -> 240 | C27: =Q11 -> 480 | D27: =Q12 -> 240 | E27: =Q13 -> 480
A28: =120.001% -> 1.20001 | B28: =R10 -> 260 | C28: =R11 -> 520 | D28: =R12 -> 260 | E28: =R13 -> 520
H30: =SUM(H6:H29) -> 1
I31: TOTAL | J31: =SUM(J6:J29) -> 4000 | K31: =SUM(K6:K29) -> 4000 | L31: =SUM(L6:L29) -> 4000 | M31: =SUM(M6:M29) -> 4120 | N31: =SUM(N6:N29) -> 4320 | O31: =SUM(O6:O29) -> 4400 | P31: =SUM(P6:P29) -> 4600 | Q31: =SUM(Q6:Q29) -> 4800 | R31: =SUM(R6:R29) -> 5200
G33: EXTRA | H33: Special KPI
H35: G1 | O35: =O6 -> 220
H36: G2 | J36: =J10 -> 200
H37: G3 | M37: =M16 -> 618
H38: Ot | M38: =M19 -> 206
H39: TOTAL | I39: =SUM(I35:R38) -> 1244
H41: Extreme | I41: <80% | J41: 80% to <90% | K41: 90% to <95% | L41: 95% to <100% | M41: 100% to <105% | N41: 105% to <110% | O41: 110% to <115% | P41: 115% to < 120% | Q41: 120% to <130% | R41: >130%
I42: 0 | J42: 1200 | K42: 1350 | L42: =1425 -> 1425 | M42: 1500 | N42: 1575 | O42: 1725 | P42: 1875 | Q42: 1950 | R42: 2100
H43: Money | J43: -0.2 | K43: -0.1 | L43: -0.05 | N43: 0.05 | O43: 0.15 | P43: 0.25 | Q43: 0.3 | R43: 0.4
H44: Option1 | I44: <80% | J44: 80% to <90% | K44: 90% to <95% | L44: 95% to <100% | M44: 1 | N44: >100% to <=105% | O44: >105% to <=110% | P44: >110% to <=115% | Q44: >115% to < =120% | R44: >120% to > 130%
H45: G1 | I45: =J6 -> 200 | J45: =J6 -> 200 | K45: =K6 -> 200 | L45: =L6 -> 200 | M45: =M6 -> 206 | N45: =N6 -> 216 | O45: =O6 -> 220 | P45: =P6 -> 230 | Q45: =Q6 -> 240 | R45: =R6 -> 260
...

Sheet  WS SF
J1: =$H$4+($H$4*J3) -> 3150 | K1: =$H$4+($H$4*K3) -> 3325
J2: 3500 | K2: 3500 | L2: =$H$4+($H$4*L3) -> 3500 | M2: =$H$4+($H$4*M3) -> 3605 | N2: =$H$4+($H$4*N3) -> 3780 | O2: =$H$4+($H$4*O3) -> 3850 | P2: =$H$4+($H$4*P3) -> 4025 | Q2: =$H$4+($H$4*Q3) -> 4200 | R2: =$H$4+($H$4*R3) -> 4550
D3: Incentive base | I3: Money | J3: -0.1 | K3: -0.05 | L3: 0 | M3: 0.03 | N3: 0.08 | O3: 0.1 | P3: 0.15 | Q3: 0.2 | R3: 0.3 | U3: Simulation
C4: Depot | D4: Now | E4: New | G4: Incentive $ | H4: 3500 | I4: GOAL | J4: 0.9 | K4: 0.95 | L4: 1 | M4: 1.03 | N4: 1.06 | O4: 1.1 | P4: 1.15 | Q4: 1.2 | R4: 1.3 | W4: 45566 | X4: 45597 | Y4: 45627 | Z4: Total
C5: Area Manger | D5: 5000 | E5: 5000 | U5: Real | V5: Sales (1-2-3-4) | W5: 5000 | X5: 5000 | Y5: 5000 | Z5: =SUM(W5:Y5) -> 15000
C6: Depocho | D6: 4000 | E6: 4000 | G6: G1(CORE) | H6: 0.05 | I6: AJINOMOTO | J6: =H6*$J$2 -> 175 | K6: =H6*$K$2 -> 175 | L6: =H6*$L$2 -> 175 | M6: =H6*$M$2 -> 180.25 | N6: =H6*$N$2 -> 189 | O6: =H6*$O$2 -> 192.5 | P6: =H6*$P$2 -> 201.25 | Q6: =H6*$Q$2 -> 210 | R6: =H6*$R$2 -> 227.5
C7: D.Depocho | D7: 4000 | E7: 4000 | H7: 0.1 | I7: ROSDEE | J7: =H7*$J$2 -> 350 | K7: =H7*$K$2 -> 350 | L7: =H7*$L$2 -> 350 | M7: =H7*$M$2 -> 360.5 | N7: =H7*$N$2 -> 378 | O7: =H7*$O$2 -> 385 | P7: =H7*$P$2 -> 402.5 | Q7: =H7*$Q$2 -> 420 | R7: =H7*$R$2 -> 455 | U7: New Metod | V7: Sales 1 | W7: 6000 | X7: 5000 | Y7: 4500 | Z7: =SUM(W7:Y7) -> 15500
C8: CV | D8: 2500 | E8: 2500 | H8: 0.1 | I8: BIRDY | J8: =H8*$J$2 -> 350 | K8: =H8*$K$2 -> 350 | L8: =H8*$L$2 -> 350 | M8: =H8*$M$2 -> 360.5 | N8: =H8*$N$2 -> 378 | O8: =H8*$O$2 -> 385 | P8: =H8*$P$2 -> 402.5 | Q8: =H8*$Q$2 -> 420 | R8: =H8*$R$2 -> 455 | V8: Sales 2 | W8: =I39 -> 1088.5 | X8: 5200 | Y8: 5000 | Z8: =SUM(W8:Y8) -> 11288.5
C9: Driver | D9: 1200 | E9: 1200 | V9: Sales3 | W9: 5000 | X9: 4900 | Y9: 6500 | Z9: =SUM(W9:Y9) -> 16400 | AA9: =Z9/Z5 -> 1.0933333
C10: CVFV | E10: 2500 | G10: G2(GD) | H10: 0.05 | I10: AJI-PLUS | J10: =H10*$J$2 -> 175 | K10: =H10*$K$2 -> 175 | L10: =H10*$L$2 -> 175 | M10: =H10*$M$2 -> 180.25 | N10: =H10*$N$2 -> 189 | O10: =H10*$O$2 -> 192.5 | P10: =H10*$P$2 -> 201.25 | Q10: =H10*$Q$2 -> 210 | R10: =H10*$R$2 -> 227.5 | V10: Sales 4 | W10: 4800 | X10: 4000 | Y10: 5000 | Z10: =SUM(W10:Y10) -> 13800
C11: WSF | E11: 3500 | H11: 0.1 | I11: ROSDEE CUBE | J11: =H11*$J$2 -> 350 | K11: =H11*$K$2 -> 350 | L11: =H11*$L$2 -> 350 | M11: =H11*$M$2 -> 360.5 | N11: =H11*$N$2 -> 378 | O11: =H11*$O$2 -> 385 | P11: =H11*$P$2 -> 402.5 | Q11: =H11*$Q$2 -> 420 | R11: =H11*$R$2 -> 455 | Y11: Average | Z11: =MEDIAN(Z7:Z10) -> 14650 | AA11: =Z11/Z5-1 -> -0.023333333
C12: WH | E12: 3500 | H12: 0.1 | I12: ROSDEE MENU | J12: =H12*$J$2 -> 350 | K12: =H12*$K$2 -> 350 | L12: =H12*$L$2 -> 350 | M12: =H12*$M$2 -> 360.5 | N12: =H12*$N$2 -> 378 | O12: =H12*$O$2 -> 385 | P12: =H12*$P$2 -> 402.5 | Q12: =H12*$Q$2 -> 420 | R12: =H12*$R$2 -> 455
H13: 0.1 | I13: ROSDEE NOODLE | J13: =H13*$J$2 -> 350 | K13: =H13*$K$2 -> 350 | L13: =H13*$L$2 -> 350 | M13: =H13*$M$2 -> 360.5 | N13: =H13*$N$2 -> 378 | O13: =H13*$O$2 -> 385 | P13: =H13*$P$2 -> 402.5 | Q13: =H13*$Q$2 -> 420 | R13: =H13*$R$2 -> 455
J14: =H14*$J$2 -> 0 | K14: =H14*$K$2 -> 0 | L14: =H14*$L$2 -> 0 | M14: =H14*$M$2 -> 0 | N14: =H14*$N$2 -> 0 | O14: =H14*$O$2 -> 0 | P14: =H14*$P$2 -> 0 | Q14: =H14*$Q$2 -> 0 | R14: =H14*$R$2 -> 0
G16: G3(BB) | H16: 0.15 | I16: YUMYUM | J16: =H16*$J$2 -> 525 | K16: =H16*$K$2 -> 525 | L16: =H16*$L$2 -> 525 | M16: =H16*$M$2 -> 540.75 | N16: =H16*$N$2 -> 567 | O16: =H16*$O$2 -> 577.5 | P16: =H16*$P$2 -> 603.75 | Q16: =H16*$Q$2 -> 630 | R16: =H16*$R$2 -> 682.5 | U16: Cascade concept
H17: 0.15 | I17: POWDER COFFEE | J17: =H17*$J$2 -> 525 | K17: =H17*$K$2 -> 525 | L17: =H17*$L$2 -> 525 | M17: =H17*$M$2 -> 540.75 | N17: =H17*$N$2 -> 567 | O17: =H17*$O$2 -> 577.5 | P17: =H17*$P$2 -> 603.75 | Q17: =H17*$Q$2 -> 630 | R17: =H17*$R$2 -> 682.5
U18: Salesman | V18: Incentive
B19: AJI Plus | C19: RDQ | D19: RDM | E19: RDNS | G19: Others | H19: 0.05 | I19: Takumi-Aji | J19: =H19*$J$2 -> 175 | K19: =H19*$K$2 -> 175 | L19: =H19*$L$2 -> 175 | M19: =H19*$M$2 -> 180.25 | N19: =H19*$N$2 -> 189 | O19: =H19*$O$2 -> 192.5 | P19: =H19*$P$2 -> 201.25 | Q19: =H19*$Q$2 -> 210 | R19: =H19*$R$2 -> 227.5
A20: 0 | B20: =J10 -> 175 | C20: =J11 -> 350 | D20: =J12 -> 350 | E20: =J13 -> 350 | H20: 0.05 | I20: ROSDEE MENU KKR | J20: =H20*$J$2 -> 175 | K20: =H20*$K$2 -> 175 | L20: =H20*$L$2 -> 175 | M20: =H20*$M$2 -> 180.25 | N20: =H20*$N$2 -> 189 | O20: =H20*$O$2 -> 192.5 | P20: =H20*$P$2 -> 201.25 | Q20: =H20*$Q$2 -> 210 | R20: =H20*$R$2 -> 227.5 | U20: All Depot Salesman | V20: Depocho | W20: incentive
A21: 0.90001 | B21: =K10 -> 175 | C21: =K11 -> 350 | D21: =K12 -> 350 | E21: =K13 -> 350
A22: 0.95001 | B22: =L10 -> 175 | C22: =L11 -> 350 | D22: =L12 -> 350 | E22: =L13 -> 350 | U22: All Area depot result | V22: Area Manager | W22: Incentive
A23: 1.00001 | B23: =M10 -> 180.25 | C23: =M11 -> 360.5 | D23: =M12 -> 360.5 | E23: =M13 -> 360.5
A24: 1.03001 | B24: =N10 -> 189 | C24: =N11 -> 378 | D24: =N12 -> 378 | E24: =N13 -> 378 | U24: All Area manager Result | V24: Division manager | W24: Incetive
A25: =106.001% -> 1.06001 | B25: =O10 -> 192.5 | C25: =O11 -> 385 | D25: =O12 -> 385 | E25: =O13 -> 385
A26: =110.001% -> 1.10001 | B26: =P10 -> 201.25 | C26: =P11 -> 402.5 | D26: =P12 -> 402.5 | E26: =P13 -> 402.5
A27: =115.001% -> 1.15001 | B27: =Q10 -> 210 | C27: =Q11 -> 420 | D27: =Q12 -> 420 | E27: =Q13 -> 420
A28: =120.001% -> 1.20001 | B28: =R10 -> 227.5 | C28: =R11 -> 455 | D28: =R12 -> 455 | E28: =R13 -> 455
H30: =SUM(H6:H29) -> 1
I31: TOTAL | J31: =SUM(J6:J29) -> 3500 | K31: =SUM(K6:K29) -> 3500 | L31: =SUM(L6:L29) -> 3500 | M31: =SUM(M6:M29) -> 3605 | N31: =SUM(N6:N29) -> 3780 | O31: =SUM(O6:O29) -> 3850 | P31: =SUM(P6:P29) -> 4025 | Q31: =SUM(Q6:Q29) -> 4200 | R31: =SUM(R6:R29) -> 4550
G33: EXTRA | H33: Special KPI
H35: G1 | O35: =O6 -> 192.5
H36: G2 | J36: =J10 -> 175
H37: G3 | M37: =M16 -> 540.75
H38: Ot | M38: =M19 -> 180.25
H39: TOTAL | I39: =SUM(I35:R38) -> 1088.5
H41: Extreme | I41: <80% | J41: 80% to <90% | K41: 90% to <95% | L41: 95% to <100% | M41: 100% to <105% | N41: 105% to <110% | O41: 110% to <115% | P41: 115% to < 120% | Q41: 120% to <130% | R41: >130%
I42: 0 | J42: 1200 | K42: 1350 | L42: =1425 -> 1425 | M42: 1500 | N42: 1575 | O42: 1725 | P42: 1875 | Q42: 1950 | R42: 2100
H43: Money | J43: -0.2 | K43: -0.1 | L43: -0.05 | N43: 0.05 | O43: 0.15 | P43: 0.25 | Q43: 0.3 | R43: 0.4
H44: Option1 | I44: <80% | J44: 80% to <90% | K44: 90% to <95% | L44: 95% to <100% | M44: 1 | N44: >100% to <=105% | O44: >105% to <=110% | P44: >110% to <=115% | Q44: >115% to < =120% | R44: >120% to > 130%
H45: G1 | I45: =J6 -> 175 | J45: =J6 -> 175 | K45: =K6 -> 175 | L45: =L6 -> 175 | M45: =M6 -> 180.25 | N45: =N6 -> 189 | O45: =O6 -> 192.5 | P45: =P6 -> 201.25 | Q45: =Q6 -> 210 | R45: =R6 -> 227.5
...

Sheet WS WH
J1: =$H$4+($H$4*J3) -> 3150 | K1: =$H$4+($H$4*K3) -> 3325
J2: 3500 | K2: 3500 | L2: =$H$4+($H$4*L3) -> 3500 | M2: =$H$4+($H$4*M3) -> 3605 | N2: =$H$4+($H$4*N3) -> 3780 | O2: =$H$4+($H$4*O3) -> 3850 | P2: =$H$4+($H$4*P3) -> 4025 | Q2: =$H$4+($H$4*Q3) -> 4200 | R2: =$H$4+($H$4*R3) -> 4550
D3: Incentive base | I3: Money | J3: -0.1 | K3: -0.05 | L3: 0 | M3: 0.03 | N3: 0.08 | O3: 0.1 | P3: 0.15 | Q3: 0.2 | R3: 0.3 | U3: Simulation
C4: Depot | D4: Now | E4: New | G4: Incentive $ | H4: 3500 | I4: GOAL | J4: 0.9 | K4: 0.95 | L4: 1 | M4: 1.03 | N4: 1.06 | O4: 1.1 | P4: 1.15 | Q4: 1.2 | R4: 1.3 | W4: 45566 | X4: 45597 | Y4: 45627 | Z4: Total
C5: Area Manger | D5: 5000 | E5: 5000 | U5: Real | V5: Sales (1-2-3-4) | W5: 5000 | X5: 5000 | Y5: 5000 | Z5: =SUM(W5:Y5) -> 15000
C6: Depocho | D6: 4000 | E6: 4000 | G6: G1(CORE) | H6: 0.1 | I6: AJINOMOTO | J6: =H6*$J$2 -> 350 | K6: =H6*$K$2 -> 350 | L6: =H6*$L$2 -> 350 | M6: =H6*$M$2 -> 360.5 | N6: =H6*$N$2 -> 378 | O6: =H6*$O$2 -> 385 | P6: =H6*$P$2 -> 402.5 | Q6: =H6*$Q$2 -> 420 | R6: =H6*$R$2 -> 455
C7: D.Depocho | D7: 4000 | E7: 4000 | H7: 0.15 | I7: ROSDEE | J7: =H7*$J$2 -> 525 | K7: =H7*$K$2 -> 525 | L7: =H7*$L$2 -> 525 | M7: =H7*$M$2 -> 540.75 | N7: =H7*$N$2 -> 567 | O7: =H7*$O$2 -> 577.5 | P7: =H7*$P$2 -> 603.75 | Q7: =H7*$Q$2 -> 630 | R7: =H7*$R$2 -> 682.5 | U7: New Metod | V7: Sales 1 | W7: 6000 | X7: 5000 | Y7: 4500 | Z7: =SUM(W7:Y7) -> 15500
C8: CV | D8: 2500 | E8: 2500 | H8: 0.25 | I8: BIRDY | J8: =H8*$J$2 -> 875 | K8: =H8*$K$2 -> 875 | L8: =H8*$L$2 -> 875 | M8: =H8*$M$2 -> 901.25 | N8: =H8*$N$2 -> 945 | O8: =H8*$O$2 -> 962.5 | P8: =H8*$P$2 -> 1006.25 | Q8: =H8*$Q$2 -> 1050 | R8: =H8*$R$2 -> 1137.5 | V8: Sales 2 | W8: =I39 -> 1100.75 | X8: 5200 | Y8: 5000 | Z8: =SUM(W8:Y8) -> 11300.75
C9: Driver | D9: 1200 | E9: 1200 | V9: Sales3 | W9: 5000 | X9: 4900 | Y9: 6500 | Z9: =SUM(W9:Y9) -> 16400 | AA9: =Z9/Z5 -> 1.0933333
C10: CVFV | E10: 2500 | G10: G2(GD) | H10: 0.05 | I10: AJI-PLUS | J10: =H10*$J$2 -> 175 | K10: =H10*$K$2 -> 175 | L10: =H10*$L$2 -> 175 | M10: =H10*$M$2 -> 180.25 | N10: =H10*$N$2 -> 189 | O10: =H10*$O$2 -> 192.5 | P10: =H10*$P$2 -> 201.25 | Q10: =H10*$Q$2 -> 210 | R10: =H10*$R$2 -> 227.5 | V10: Sales 4 | W10: 4800 | X10: 4000 | Y10: 5000 | Z10: =SUM(W10:Y10) -> 13800
C11: WSF | E11: 3500 | H11: 0.05 | I11: ROSDEE CUBE | J11: =H11*$J$2 -> 175 | K11: =H11*$K$2 -> 175 | L11: =H11*$L$2 -> 175 | M11: =H11*$M$2 -> 180.25 | N11: =H11*$N$2 -> 189 | O11: =H11*$O$2 -> 192.5 | P11: =H11*$P$2 -> 201.25 | Q11: =H11*$Q$2 -> 210 | R11: =H11*$R$2 -> 227.5 | Y11: Average | Z11: =MEDIAN(Z7:Z10) -> 14650 | AA11: =Z11/Z5-1 -> -0.023333333
C12: WH | E12: 3500 | H12: 0.05 | I12: ROSDEE MENU | J12: =H12*$J$2 -> 175 | K12: =H12*$K$2 -> 175 | L12: =H12*$L$2 -> 175 | M12: =H12*$M$2 -> 180.25 | N12: =H12*$N$2 -> 189 | O12: =H12*$O$2 -> 192.5 | P12: =H12*$P$2 -> 201.25 | Q12: =H12*$Q$2 -> 210 | R12: =H12*$R$2 -> 227.5
H13: 0.05 | I13: ROSDEE NOODLE | J13: =H13*$J$2 -> 175 | K13: =H13*$K$2 -> 175 | L13: =H13*$L$2 -> 175 | M13: =H13*$M$2 -> 180.25 | N13: =H13*$N$2 -> 189 | O13: =H13*$O$2 -> 192.5 | P13: =H13*$P$2 -> 201.25 | Q13: =H13*$Q$2 -> 210 | R13: =H13*$R$2 -> 227.5
J14: =H14*$J$2 -> 0 | K14: =H14*$K$2 -> 0 | L14: =H14*$L$2 -> 0 | M14: =H14*$M$2 -> 0 | N14: =H14*$N$2 -> 0 | O14: =H14*$O$2 -> 0 | P14: =H14*$P$2 -> 0 | Q14: =H14*$Q$2 -> 0 | R14: =H14*$R$2 -> 0
G16: G3(BB) | H16: 0.1 | I16: YUMYUM | J16: =H16*$J$2 -> 350 | K16: =H16*$K$2 -> 350 | L16: =H16*$L$2 -> 350 | M16: =H16*$M$2 -> 360.5 | N16: =H16*$N$2 -> 378 | O16: =H16*$O$2 -> 385 | P16: =H16*$P$2 -> 402.5 | Q16: =H16*$Q$2 -> 420 | R16: =H16*$R$2 -> 455 | U16: Cascade concept
H17: 0.1 | I17: POWDER COFFEE | J17: =H17*$J$2 -> 350 | K17: =H17*$K$2 -> 350 | L17: =H17*$L$2 -> 350 | M17: =H17*$M$2 -> 360.5 | N17: =H17*$N$2 -> 378 | O17: =H17*$O$2 -> 385 | P17: =H17*$P$2 -> 402.5 | Q17: =H17*$Q$2 -> 420 | R17: =H17*$R$2 -> 455
U18: Salesman | V18: Incentive
B19: AJI Plus | C19: RDQ | D19: RDM | E19: RDNS | G19: Others | H19: 0.05 | I19: Takumi-Aji | J19: =H19*$J$2 -> 175 | K19: =H19*$K$2 -> 175 | L19: =H19*$L$2 -> 175 | M19: =H19*$M$2 -> 180.25 | N19: =H19*$N$2 -> 189 | O19: =H19*$O$2 -> 192.5 | P19: =H19*$P$2 -> 201.25 | Q19: =H19*$Q$2 -> 210 | R19: =H19*$R$2 -> 227.5
A20: 0 | B20: =J10 -> 175 | C20: =J11 -> 175 | D20: =J12 -> 175 | E20: =J13 -> 175 | H20: 0.05 | I20: ROSDEE MENU KKR | J20: =H20*$J$2 -> 175 | K20: =H20*$K$2 -> 175 | L20: =H20*$L$2 -> 175 | M20: =H20*$M$2 -> 180.25 | N20: =H20*$N$2 -> 189 | O20: =H20*$O$2 -> 192.5 | P20: =H20*$P$2 -> 201.25 | Q20: =H20*$Q$2 -> 210 | R20: =H20*$R$2 -> 227.5 | U20: All Depot Salesman | V20: Depocho | W20: incentive
A21: 0.90001 | B21: =K10 -> 175 | C21: =K11 -> 175 | D21: =K12 -> 175 | E21: =K13 -> 175
A22: 0.95001 | B22: =L10 -> 175 | C22: =L11 -> 175 | D22: =L12 -> 175 | E22: =L13 -> 175 | U22: All Area depot result | V22: Area Manager | W22: Incentive
A23: 1.00001 | B23: =M10 -> 180.25 | C23: =M11 -> 180.25 | D23: =M12 -> 180.25 | E23: =M13 -> 180.25
A24: 1.03001 | B24: =N10 -> 189 | C24: =N11 -> 189 | D24: =N12 -> 189 | E24: =N13 -> 189 | U24: All Area manager Result | V24: Division manager | W24: Incetive
A25: =106.001% -> 1.06001 | B25: =O10 -> 192.5 | C25: =O11 -> 192.5 | D25: =O12 -> 192.5 | E25: =O13 -> 192.5
A26: =110.001% -> 1.10001 | B26: =P10 -> 201.25 | C26: =P11 -> 201.25 | D26: =P12 -> 201.25 | E26: =P13 -> 201.25
A27: =115.001% -> 1.15001 | B27: =Q10 -> 210 | C27: =Q11 -> 210 | D27: =Q12 -> 210 | E27: =Q13 -> 210
A28: =120.001% -> 1.20001 | B28: =R10 -> 227.5 | C28: =R11 -> 227.5 | D28: =R12 -> 227.5 | E28: =R13 -> 227.5
H30: =SUM(H6:H29) -> 1
I31: TOTAL | J31: =SUM(J6:J29) -> 3500 | K31: =SUM(K6:K29) -> 3500 | L31: =SUM(L6:L29) -> 3500 | M31: =SUM(M6:M29) -> 3605 | N31: =SUM(N6:N29) -> 3780 | O31: =SUM(O6:O29) -> 3850 | P31: =SUM(P6:P29) -> 4025 | Q31: =SUM(Q6:Q29) -> 4200 | R31: =SUM(R6:R29) -> 4550
G33: EXTRA | H33: Special KPI
H35: G1 | O35: =O6 -> 385
H36: G2 | J36: =J10 -> 175
H37: G3 | M37: =M16 -> 360.5
H38: Ot | M38: =M19 -> 180.25
H39: TOTAL | I39: =SUM(I35:R38) -> 1100.75
H41: Extreme | I41: <80% | J41: 80% to <90% | K41: 90% to <95% | L41: 95% to <100% | M41: 100% to <105% | N41: 105% to <110% | O41: 110% to <115% | P41: 115% to < 120% | Q41: 120% to <130% | R41: >130%
I42: 0 | J42: 1200 | K42: 1350 | L42: =1425 -> 1425 | M42: 1500 | N42: 1575 | O42: 1725 | P42: 1875 | Q42: 1950 | R42: 2100
H43: Money | J43: -0.2 | K43: -0.1 | L43: -0.05 | N43: 0.05 | O43: 0.15 | P43: 0.25 | Q43: 0.3 | R43: 0.4
H44: Option1 | I44: <80% | J44: 80% to <90% | K44: 90% to <95% | L44: 95% to <100% | M44: 1 | N44: >100% to <=105% | O44: >105% to <=110% | P44: >110% to <=115% | Q44: >115% to < =120% | R44: >120% to > 130%
H45: G1 | I45: =J6 -> 350 | J45: =J6 -> 350 | K45: =K6 -> 350 | L45: =L6 -> 350 | M45: =M6 -> 360.5 | N45: =N6 -> 378 | O45: =O6 -> 385 | P45: =P6 -> 402.5 | Q45: =Q6 -> 420 | R45: =R6 -> 455
...

Sheet Test
A1: Row Labels | E1: 1 | F1: 2 | G1: 3 | H1: 4 | I1: 5 | J1: 6 | K1: 7 | L1: 8 | M1: 9 | N1: 10 | O1: 11 | P1: 12 | Q1: 13 | R1: 14 | S1: 15 | T1: 16 | U1: 17 | V1: 18 | W1: 19
A2: 1190011201 | B2: 76001 | C2: MR.X | D2: =VLOOKUP(A2,'Actual_Aji Plus'!#REF!,2,0) -> #REF! | E2: 0.9 | F2: 0.9001 | G2: 0.95 | H2: 0.9501 | I2: 1 | J2: 1.0001 | K2: 1.03 | L2: 1.0301 | M2: 1.06 | N2: 1.0601 | O2: 1.1 | P2: 1.1001 | Q2: 1.15 | R2: 1.1501 | S2: 1.2 | T2: 1.2001 | U2: 1.7 | V2: 0.8 | W2: 0.55
E4: 1 | F4: 2 | G4: 3 | H4: 4 | I4: 5 | J4: 6 | K4: 7 | L4: 8 | M4: 9 | N4: 10 | O4: 11 | P4: 12 | Q4: 13 | R4: 14 | S4: 15 | T4: 16 | U4: 17 | V4: 18 | W4: 19
E5: =IFERROR(VLOOKUP(E2,'Top WS'!$A$19:$B$28,2),0) -> 200 | F5: =IFERROR(VLOOKUP(F2,'Top WS'!$A$19:$B$28,2),0) -> 200 | G5: =IFERROR(VLOOKUP(G2,'Top WS'!$A$19:$B$28,2),0) -> 200 | H5: =IFERROR(VLOOKUP(H2,'Top WS'!$A$19:$B$28,2),0) -> 200 | I5: =IFERROR(VLOOKUP(I2,'Top WS'!$A$19:$B$28,2),0) -> 200 | J5: =IFERROR(VLOOKUP(J2,'Top WS'!$A$19:$B$28,2),0) -> 206 | K5: =IFERROR(VLOOKUP(K2,'Top WS'!$A$19:$B$28,2),0) -> 206 | L5: =IFERROR(VLOOKUP(L2,'Top WS'!$A$19:$B$28,2),0) -> 216 | ... W5: =IFERROR(VLOOKUP(W2,'Top WS'!$A$19:$B$28,2),0) -> 200

Sheet SF WH
J1: =$H$4+($H$4*J3) -> 3150 | K1: =$H$4+($H$4*K3) -> 3325
J2: 3500 | K2: 3500 | L2: =$H$4+($H$4*L3) -> 3500 | M2: =$H$4+($H$4*M3) -> 3605 | N2: =$H$4+($H$4*N3) -> 3780 | O2: =$H$4+($H$4*O3) -> 3850 | P2: =$H$4+($H$4*P3) -> 4025 | Q2: =$H$4+($H$4*Q3) -> 4200 | R2: =$H$4+($H$4*R3) -> 4550
D3: Incentive base | I3: Money | J3: -0.1 | K3: -0.05 | L3: 0 | M3: 0.03 | N3: 0.08 | O3: 0.1 | P3: 0.15 | Q3: 0.2 | R3: 0.3 | U3: Simulation
C4: Depot | D4: Now | E4: New | G4: Incentive $ | H4: 3500 | I4: GOAL | J4: 0.9 | K4: 0.95 | L4: 1 | M4: 1.03 | N4: 1.06 | O4: 1.1 | P4: 1.15 | Q4: 1.2 | R4: 1.3 | W4: 45566 | X4: 45597 | Y4: 45627 | Z4: Total
C5: Area Manger | D5: 5000 | E5: 5000 | U5: Real | V5: Sales (1-2-3-4) | W5: 5000 | X5: 5000 | Y5: 5000 | Z5: =SUM(W5:Y5) -> 15000
C6: Depocho | D6: 4000 | E6: 4000 | G6: G1(CORE) | H6: 0.08 | I6: AJINOMOTO | J6: =H6*$J$2 -> 280 | K6: =H6*$K$2 -> 280 | L6: =H6*$L$2 -> 280 | M6: =H6*$M$2 -> 288.4 | N6: =H6*$N$2 -> 302.4 | O6: =H6*$O$2 -> 308 | P6: =H6*$P$2 -> 322 | Q6: =H6*$Q$2 -> 336 | R6: =H6*$R$2 -> 364
C7: D.Depocho | D7: 4000 | E7: 4000 | H7: 0.13 | I7: ROSDEE | J7: =H7*$J$2 -> 455 | K7: =H7*$K$2 -> 455 | L7: =H7*$L$2 -> 455 | M7: =H7*$M$2 -> 468.65 | N7: =H7*$N$2 -> 491.4 | O7: =H7*$O$2 -> 500.5 | P7: =H7*$P$2 -> 523.25 | Q7: =H7*$Q$2 -> 546 | R7: =H7*$R$2 -> 591.5 | U7: New Metod | V7: Sales 1 | W7: 6000 | X7: 5000 | Y7: 4500 | Z7: =SUM(W7:Y7) -> 15500
C8: CV | D8: 2500 | E8: 2500 | H8: 0.18 | I8: BIRDY | J8: =H8*$J$2 -> 630 | K8: =H8*$K$2 -> 630 | L8: =H8*$L$2 -> 630 | M8: =H8*$M$2 -> 648.9 | N8: =H8*$N$2 -> 680.4 | O8: =H8*$O$2 -> 693 | P8: =H8*$P$2 -> 724.5 | Q8: =H8*$Q$2 -> 756 | R8: =H8*$R$2 -> 819 | V8: Sales 2 | W8: =I39 -> 1131.9 | X8: 5200 | Y8: 5000 | Z8: =SUM(W8:Y8) -> 11331.9
C9: Driver | D9: 1200 | E9: 1200 | V9: Sales3 | W9: 5000 | X9: 4900 | Y9: 6500 | Z9: =SUM(W9:Y9) -> 16400 | AA9: =Z9/Z5 -> 1.0933333
C10: CVFV | E10: 2500 | G10: G2(GD) | H10: 0.05 | I10: AJI-PLUS | J10: =H10*$J$2 -> 175 | K10: =H10*$K$2 -> 175 | L10: =H10*$L$2 -> 175 | M10: =H10*$M$2 -> 180.25 | N10: =H10*$N$2 -> 189 | O10: =H10*$O$2 -> 192.5 | P10: =H10*$P$2 -> 201.25 | Q10: =H10*$Q$2 -> 210 | R10: =H10*$R$2 -> 227.5 | V10: Sales 4 | W10: 4800 | X10: 4000 | Y10: 5000 | Z10: =SUM(W10:Y10) -> 13800
C11: WSF | E11: 3500 | H11: 0.06 | I11: ROSDEE CUBE | J11: =H11*$J$2 -> 210 | K11: =H11*$K$2 -> 210 | L11: =H11*$L$2 -> 210 | M11: =H11*$M$2 -> 216.3 | N11: =H11*$N$2 -> 226.8 | O11: =H11*$O$2 -> 231 | P11: =H11*$P$2 -> 241.5 | Q11: =H11*$Q$2 -> 252 | R11: =H11*$R$2 -> 273 | Y11: Average | Z11: =MEDIAN(Z7:Z10) -> 14650 | AA11: =Z11/Z5-1 -> -0.023333333
C12: WH | E12: 3500 | H12: 0.07 | I12: ROSDEE MENU | J12: =H12*$J$2 -> 245 | K12: =H12*$K$2 -> 245 | L12: =H12*$L$2 -> 245 | M12: =H12*$M$2 -> 252.35 | N12: =H12*$N$2 -> 264.6 | O12: =H12*$O$2 -> 269.5 | P12: =H12*$P$2 -> 281.75 | Q12: =H12*$Q$2 -> 294 | R12: =H12*$R$2 -> 318.5
H13: 0.07 | I13: ROSDEE NOODLE | J13: =H13*$J$2 -> 245 | K13: =H13*$K$2 -> 245 | L13: =H13*$L$2 -> 245 | M13: =H13*$M$2 -> 252.35 | N13: =H13*$N$2 -> 264.6 | O13: =H13*$O$2 -> 269.5 | P13: =H13*$P$2 -> 281.75 | Q13: =H13*$Q$2 -> 294 | R13: =H13*$R$2 -> 318.5
J14: =H14*$J$2 -> 0 | K14: =H14*$K$2 -> 0 | L14: =H14*$L$2 -> 0 | M14: =H14*$M$2 -> 0 | N14: =H14*$N$2 -> 0 | O14: =H14*$O$2 -> 0 | P14: =H14*$P$2 -> 0 | Q14: =H14*$Q$2 -> 0 | R14: =H14*$R$2 -> 0
G16: G3(BB) | H16: 0.13 | I16: YUMYUM | J16: =H16*$J$2 -> 455 | K16: =H16*$K$2 -> 455 | L16: =H16*$L$2 -> 455 | M16: =H16*$M$2 -> 468.65 | N16: =H16*$N$2 -> 491.4 | O16: =H16*$O$2 -> 500.5 | P16: =H16*$P$2 -> 523.25 | Q16: =H16*$Q$2 -> 546 | R16: =H16*$R$2 -> 591.5 | U16: Cascade concept
H17: 0.13 | I17: POWDER COFFEE | J17: =H17*$J$2 -> 455 | K17: =H17*$K$2 -> 455 | L17: =H17*$L$2 -> 455 | M17: =H17*$M$2 -> 468.65 | N17: =H17*$N$2 -> 491.4 | O17: =H17*$O$2 -> 500.5 | P17: =H17*$P$2 -> 523.25 | Q17: =H17*$Q$2 -> 546 | R17: =H17*$R$2 -> 591.5
U18: Salesman | V18: Incentive
B19: AJI Plus | C19: RDQ | D19: RDM | E19: RDNS | G19: Others | H19: 0.05 | I19: Takumi-Aji | J19: =H19*$J$2 -> 175 | K19: =H19*$K$2 -> 175 | L19: =H19*$L$2 -> 175 | M19: =H19*$M$2 -> 180.25 | N19: =H19*$N$2 -> 189 | O19: =H19*$O$2 -> 192.5 | P19: =H19*$P$2 -> 201.25 | Q19: =H19*$Q$2 -> 210 | R19: =H19*$R$2 -> 227.5
A20: 0 | B20: =J10 -> 175 | C20: =J11 -> 210 | D20: =J12 -> 245 | E20: =J13 -> 245 | H20: 0.05 | I20: ROSDEE MENU KKR | J20: =H20*$J$2 -> 175 | K20: =H20*$K$2 -> 175 | L20: =H20*$L$2 -> 175 | M20: =H20*$M$2 -> 180.25 | N20: =H20*$N$2 -> 189 | O20: =H20*$O$2 -> 192.5 | P20: =H20*$P$2 -> 201.25 | Q20: =H20*$Q$2 -> 210 | R20: =H20*$R$2 -> 227.5 | U20: All Depot Salesman | V20: Depocho | W20: incentive
A21: 0.90001 | B21: =K10 -> 175 | C21: =K11 -> 210 | D21: =K12 -> 245 | E21: =K13 -> 245
A22: 0.95001 | B22: =L10 -> 175 | C22: =L11 -> 210 | D22: =L12 -> 245 | E22: =L13 -> 245 | U22: All Area depot result | V22: Area Manager | W22: Incentive
A23: 1.00001 | B23: =M10 -> 180.25 | C23: =M11 -> 216.3 | D23: =M12 -> 252.35 | E23: =M13 -> 252.35
A24: 1.03001 | B24: =N10 -> 189 | C24: =N11 -> 226.8 | D24: =N12 -> 264.6 | E24: =N13 -> 264.6 | U24: All Area manager Result | V24: Division manager | W24: Incetive
A25: =106.001% -> 1.06001 | B25: =O10 -> 192.5 | C25: =O11 -> 231 | D25: =O12 -> 269.5 | E25: =O13 -> 269.5
A26: =110.001% -> 1.10001 | B26: =P10 -> 201.25 | C26: =P11 -> 241.5 | D26: =P12 -> 281.75 | E26: =P13 -> 281.75
A27: =115.001% -> 1.15001 | B27: =Q10 -> 210 | C27: =Q11 -> 252 | D27: =Q12 -> 294 | E27: =Q13 -> 294
A28: =120.001% -> 1.20001 | B28: =R10 -> 227.5 | C28: =R11 -> 273 | D28: =R12 -> 318.5 | E28: =R13 -> 318.5
H30: =SUM(H6:H29) -> 1
I31: TOTAL | J31: =SUM(J6:J29) -> 3500 | K31: =SUM(K6:K29) -> 3500 | L31: =SUM(L6:L29) -> 3500 | M31: =SUM(M6:M29) -> 3605 | N31: =SUM(N6:N29) -> 3780 | O31: =SUM(O6:O29) -> 3850 | P31: =SUM(P6:P29) -> 4025 | Q31: =SUM(Q6:Q29) -> 4200 | R31: =SUM(R6:R29) -> 4550
G33: EXTRA | H33: Special KPI
H35: G1 | O35: =O6 -> 308
H36: G2 | J36: =J10 -> 175
H37: G3 | M37: =M16 -> 468.65
H38: Ot | M38: =M19 -> 180.25
H39: TOTAL | I39: =SUM(I35:R38) -> 1131.9
H41: Extreme | I41: <80% | J41: 80% to <90% | K41: 90% to <95% | L41: 95% to <100% | M41: 100% to <105% | N41: 105% to <110% | O41: 110% to <115% | P41: 115% to < 120% | Q41: 120% to <130% | R41: >130%
I42: 0 | J42: 1200 | K42: 1350 | L42: =1425 -> 1425 | M42: 1500 | N42: 1575 | O42: 1725 | P42: 1875 | Q42: 1950 | R42: 2100
H43: Money | J43: -0.2 | K43: -0.1 | L43: -0.05 | N43: 0.05 | O43: 0.15 | P43: 0.25 | Q43: 0.3 | R43: 0.4
H44: Option1 | I44: <80% | J44: 80% to <90% | K44: 90% to <95% | L44: 95% to <100% | M44: 1 | N44: >100% to <=105% | O44: >105% to <=110% | P44: >110% to <=115% | Q44: >115% to < =120% | R44: >120% to > 130%
H45: G1 | I45: =J6 -> 280 | J45: =J6 -> 280 | K45: =K6 -> 280 | L45: =L6 -> 280 | M45: =M6 -> 288.4 | N45: =N6 -> 302.4 | O45: =O6 -> 308 | P45: =P6 -> 322 | Q45: =Q6 -> 336 | R45: =R6 -> 364
...

Sheet Guide
A1: Sale Incentive Guide
A3: Annually
A4: Step No. | B4: Sheet | C4: Step detail
A5: 1 | B5: M_Month | C5: Set the Sales Incentive payment cycle to once per year.
A7: Monthly
A8: Step No. | B8: Sheet | C8: Step detail
A9: 1 | B9: Period | C9: Define the Sales Incentive period.
A10: 2 | B10: Actual | C10: Download data from BI and copy it into the Actual sheet.
A11: 3 | B11: AST_Base | C11: Update the data in the AST Base sheet and copy the formulas in the yellow-highlighted columns.
A12: 4 | B12: HR Rep | C12: Download Personal Employment (Main & Active)_AST report from HCM, Update the data in the HR Rep and copy the formulas in the yellow-highlighted columns.
A13: 5 | B13: For HR | C13: Enter the employee ID, then copy all formulas except the Employee ID and Payment Method columns.
A15: As needed
A16: Step No. | B16: Sheet | C16: Step detail
A17: 1 | B17: T_SectAbove | C17: Adjust the compensation rate based on position level.
A18: 2 | B18: Table | C18: Adjust the compensation rate based on Job Function.
A19: 3 | B19: Target & Cal | C19: Adjust sales targets based on business conditions.
A20: 4 | B20: Shortage | C20: Adjust shortages by product and month.
A21: 5 | B21: Fix Rate | C21: Adjust fixed rate based on employee.
A23: ***Please ensure that sales and employee data align with the Sales Incentive period for that month.
A25: Recheck Job Function

Sheet M_Month
A1: sales incentive ของเดือน | B1: รอบการจ่าย Incentive (Variable) | C1: รอบการจ่าย Incentive (Fixed) | D1: Default column
A2: 46113 | B2: 46174 | C2: 46143 | D2: 1
A3: 46143 | B3: 46204 | C3: 46174 | D3: 2
A4: 46174 | B4: 46235 | C4: 46204 | D4: 3
A5: 46204 | B5: 46266 | C5: 46235 | D5: 4
A6: 46235 | B6: 46296 | C6: 46266 | D6: 5
A7: 46266 | B7: 46327 | C7: 46296 | D7: 6
A8: 46296 | B8: 46357 | C8: 46327 | D8: 7
A9: 46327 | B9: 46388 | C9: 46357 | D9: 8
A10: 46357 | B10: 46419 | C10: 46388 | D10: 9
A11: 46388 | B11: 46447 | C11: 46419 | D11: 10
A12: 46419 | B12: 46478 | C12: 46447 | D12: 11
A13: 46447 | B13: 46508 | C13: 46478 | D13: 12

Sheet Product
A1: Product
A2: AJINOMOTO
A3: ROSDEE
A4: BIRDY
A5: YUMYUM
A6: POWDER COFFEE
A7: AJI-PLUS
A8: ROSDEE MENU
A9: Takumi-Aji
A10: ROSDEE CUBE
A11: ROSDEE MENU KKR
A12: ROSDEE NOODLE

Sheet Period
A1: sales incentive ของเดือน | B1: รอบการจ่าย Incentive (Variable) | C1: รอบการจ่าย Incentive (Fixed) | D1: Default column
A2: 46113 | B2: =VLOOKUP(A2,M_Month!A:B,2,FALSE) -> 46174 | C2: =VLOOKUP(A2,M_Month!A:D,3,FALSE) -> 46143 | D2: =VLOOKUP(A2,M_Month!A:E,4,FALSE) -> 1

Sheet T_SectAbove
A1: Position Level | B1: Compensation rate
A2: Division Manager | B2: 5000
A3: Department Manager | B3: 5000
A4: Section Manager | B4: 4000
A5: Associate Director | B5: 6000

Sheet ASTBase
A1: เดือน | B1: ปี | C1: Area | D1: Depot | E1: Salesman Code | F1: รหัสพนักงาน (พนักงานขาย) | G1: ชื่อ - นามสกุล (พนักงานขาย) | H1: รหัสพนักงาน (พนักงานผู้ช่วยขาย) | I1: ชื่อ - นามสกุล (พนักงานผู้ช่วยขาย) | J1: สถานะพนักงาน (พนักงานผู้ช่วยขาย) | K1: ทีม | L1: ทะเบียนรถ | M1: ประเภทรถยนต์ | N1: หมายเหตุ | O1: ตรวจสอบ | P1: Salesman Code | Q1: DirectSupCode | R1: DeptMgrCode | S1: DivMgrCode
A2: December | B2: 2025 | F2: 222222 | P2: 0 | Q2: #N/A | R2: 0 | S2: 0
A3: December | B3: 2025 | F3: 222223 | P3: 0 | Q3: 222222 | R3: 222223 | S3: 0
A4: December | B4: 2025 | F4: 222234 | P4: 0 | Q4: 222222 | R4: 222234 | S4: 0
A5: December | B5: 2025 | F5: 222235 | P5: 0 | Q5: 222223 | R5: 222223 | S5: 0
A6: December | B6: 2025 | F6: 222236 | P6: 0 | Q6: 222234 | R6: 222234 | S6: 0
A7: December | B7: 2025 | F7: 222237 | P7: 0 | Q7: 222223 | R7: 222223 | S7: 0
A8: December | B8: 2025 | F8: 222238 | P8: 0 | Q8: 222234 | R8: 222234 | S8: 0
A9: December | B9: 2025 | F9: 222208 | P9: 0 | Q9: 222234 | R9: 222234 | S9: 0
A10: December | B10: 2025 | E10: 5490000718 | F10: 222209 | P10: 5490000718 | Q10: 222208 | R10: 222234 | S10: 0
A11: December | B11: 2025 | E11: 5490000706 | F11: 222210 | P11: 5490000706 | Q11: 222208 | R11: 222234 | S11: 0
A12: December | B12: 2025 | E12: 5490000707 | F12: 222211 | P12: 5490000707 | Q12: 222208 | R12: 222234 | S12: 0
A13: December | B13: 2025 | E13: 5490000701 | F13: 222212 | P13: 5490000701 | Q13: 222208 | R13: 222234 | S13: 0
A14: December | B14: 2025 | E14: 5490000721 | F14: 222218 | P14: 5490000721 | Q14: 222208 | R14: 222234 | S14: 0
A15: December | B15: 2025 | E15: 5490000719 | F15: 222219 | P15: 5490000719 | Q15: 222208 | R15: 222234 | S15: 0
A16: December | B16: 2025 | E16: 5490000725 | F16: 222220 | P16: 5490000725 | Q16: 222238 | R16: 222234 | S16: 0
A17: December | B17: 2025 | E17: 5490000702 | F17: 222201 | P17: 5490000702 | Q17: 222238 | R17: 222234 | S17: 0
A18: December | B18: 2025 | E18: 5490000708 | F18: 222202 | P18: 5490000708 | Q18: 222238 | R18: 222234 | S18: 0
A19: December | B19: 2025 | E19: 5490000704 | F19: 222203 | P19: 5490000704 | Q19: 222238 | R19: 222234 | S19: 0
A20: December | B20: 2025 | E20: 5490000717 | F20: 222204 | P20: 5490000717 | Q20: 222237 | R20: 222223 | S20: 0
A21: December | B21: 2025 | E21: 5490000703 | F21: 222205 | P21: 5490000703 | Q21: 222237 | R21: 222223 | S21: 0
A22: December | B22: 2025 | E22: 5490000709 | F22: 222206 | P22: 5490000709 | Q22: 222237 | R22: 222223 | S22: 0
A23: December | B23: 2025 | E23: 5490000713 | F23: 222213 | P23: 5490000713 | Q23: 222237 | R23: 222223 | S23: 0
... A28: December | B28: 2025 | E28: 5490000711 | F28: 222229 | P28: 5490000711 | Q28: 222235 | R28: 222223 | S28: 0

Sheet Actual
A1: Salesman Code | B1: Merge | C1: Salesman BI | D1: Product Group | E1: April | F1: May | G1: June | H1: July | I1: August | J1: September | K1: October | L1: November | M1: December | N1: January | O1: February | P1: March
A2: =_xlfn.IFNA(VLOOKUP(B2,Mapping!C:D,2,FALSE),C2) -> 5490000725 | B2: =C2&D2 -> 5490000725BD | C2: 5490000725 | D2: BD | N2: 54159 | O2: 72860 | P2: 77301
A3: =_xlfn.IFNA(VLOOKUP(B3,Mapping!C:D,2,FALSE),C3) -> 5490000725 | B3: =C3&D3 -> 5490000725YY | C3: 5490000725 | D3: YY | N3: 4683 | O3: 5155 | P3: 3892
A4: =_xlfn.IFNA(VLOOKUP(B4,Mapping!C:D,2,FALSE),C4) -> 5490000725 | B4: =C4&D4 -> 5490000725AJ | C4: 5490000725 | D4: AJ | N4: 3291.2 | O4: 3803 | P4: 3996.4
A5: =_xlfn.IFNA(VLOOKUP(B5,Mapping!C:D,2,FALSE),C5) -> 5490000725 | B5: =C5&D5 -> 5490000725RD | C5: 5490000725 | D5: RD | N5: 1525.26 | O5: 1817.36 | P5: 2096.1
A6: =_xlfn.IFNA(VLOOKUP(B6,Mapping!C:D,2,FALSE),C6) -> 5490000725 | B6: =C6&D6 -> 5490000725PDC | C6: 5490000725 | D6: PDC | N6: 702.8496 | O6: 857.4606 | P6: 722.9904
A7: =_xlfn.IFNA(VLOOKUP(B7,Mapping!C:D,2,FALSE),C7) -> 5490000725 | B7: =C7&D7 -> 5490000725AJP | C7: 5490000725 | D7: AJP | N7: 493.92 | O7: 504 | P7: 362.88
A8: =_xlfn.IFNA(VLOOKUP(B8,Mapping!C:D,2,FALSE),C8) -> 5490000725 | B8: =C8&D8 -> 5490000725RDC | C8: 5490000725 | D8: RDC | N8: 702.72 | O8: 178.56 | P8: 126.72
A9: =_xlfn.IFNA(VLOOKUP(B9,Mapping!C:D,2,FALSE),C9) -> 5490000725 | B9: =C9&D9 -> 5490000725TKM | C9: 5490000725 | D9: TKM | N9: 136.8 | O9: 232.8 | P9: 141.6
A10: =_xlfn.IFNA(VLOOKUP(B10,Mapping!C:D,2,FALSE),C10) -> 5490000725 | B10: =C10&D10 -> 5490000725RM | C10: 5490000725 | D10: RM | N10: 62 | O10: 128.2 | P10: 64.8
A11: =_xlfn.IFNA(VLOOKUP(B11,Mapping!C:D,2,FALSE),C11) -> 5490000725 | B11: =C11&D11 -> 5490000725RKR | C11: 5490000725 | D11: RKR | N11: 25.2 | O11: 14.4 | P11: 14.4
A12: =_xlfn.IFNA(VLOOKUP(B12,Mapping!C:D,2,FALSE),C12) -> 5490000725 | B12: =C12&D12 -> 5490000725QM | C12: 5490000725 | D12: QM | N12: 16 | O12: 13 | P12: 8
A13: =_xlfn.IFNA(VLOOKUP(B13,Mapping!C:D,2,FALSE),C13) -> 1190064722 | B13: =C13&D13 -> 1190064722RD | C13: 1190064722 | D13: RD | E13: 532387.36 | F13: 455190.7 | G13: 464090.4 | H13: 449158.1 | I13: 30232
A14: =_xlfn.IFNA(VLOOKUP(B14,Mapping!C:D,2,FALSE),C14) -> 1190064722 | B14: =C14&D14 -> 1190064722AJ | C14: 1190064722 | D14: AJ | E14: 379972.1 | F14: 305303.1 | G14: 237457.6 | H14: 302376.1 | I14: 7856
A15: =_xlfn.IFNA(VLOOKUP(B15,Mapping!C:D,2,FALSE),C15) -> 1190064722 | B15: =C15&D15 -> 1190064722YY | C15: 1190064722 | D15: YY | E15: 234275 | F15: 220342 | G15: 211946 | H15: 270053 | I15: 9806
A16: =_xlfn.IFNA(VLOOKUP(B16,Mapping!C:D,2,FALSE),C16) -> 1190064722 | B16: =C16&D16 -> 1190064722BD | C16: 1190064722 | D16: BD | E16: 102602 | F16: 111639 | G16: 156116 | H16: 152244 | I16: 756
A17: =_xlfn.IFNA(VLOOKUP(B17,Mapping!C:D,2,FALSE),C17) -> 1190064722 | B17: =C17&D17 -> 1190064722PDC | C17: 1190064722 | D17: PDC | E17: 63013.214 | F17: 37471.603 | G17: 34061.271 | H17: 38720.305 | I17: 4823.1648
A18: =_xlfn.IFNA(VLOOKUP(B18,Mapping!C:D,2,FALSE),C18) -> 1190064722 | B18: =C18&D18 -> 1190064722TKM | C18: 1190064722 | D18: TKM | E18: 35876.4 | F18: 30744 | G18: 28983.6 | H18: 51828 | I18: 2808
A19: =_xlfn.IFNA(VLOOKUP(B19,Mapping!C:D,2,FALSE),C19) -> 1190064722 | B19: =C19&D19 -> 1190064722RM | C19: 1190064722 | D19: RM | E19: 32320.9 | F19: 27392.1 | G19: 24362.4 | H19: 29863.9 | I19: 1166.5
A20: =_xlfn.IFNA(VLOOKUP(B20,Mapping!C:D,2,FALSE),C20) -> 1190064722 | B20: =C20&D20 -> 1190064722RDC | C20: 1190064722 | D20: RDC | E20: 22019.04 | F20: 19909.44 | G20: 15828.192 | H20: 16240.032 | I20: 1908.864
A21: =_xlfn.IFNA(VLOOKUP(B21,Mapping!C:D,2,FALSE),C21) -> 1190064722 | B21: =C21&D21 -> 1190064722AJP | C21: 1190064722 | D21: AJP | E21: 15906.24 | F21: 12176.64 | G21: 10120.32 | H21: 12952.8 | I21: 715.68
A22: =_xlfn.IFNA(VLOOKUP(B22,Mapping!C:D,2,FALSE),C22) -> 1190064722 | B22: =C22&D22 -> 1190064722RKR | C22: 1190064722 | D22: RKR | E22: 16165.2 | F22: 10859.4 | G22: 11651.4 | H22: 4128
A23: =_xlfn.IFNA(VLOOKUP(B23,Mapping!C:D,2,FALSE),C23) -> 1190064722 | B23: =C23&D23 -> 1190064722ND | C23: 1190064722 | D23: ND | E23: 2351.72 | F23: 2305.74 | G23: 2917.56 | H23: 2132.66 | I23: 196.02
A24: =_xlfn.IFNA(VLOOKUP(B24,Mapping!C:D,2,FALSE),C24) -> 1190064722 | B24: =C24&D24 -> 1190064722FP | C24: 1190064722 | D24: FP | E24: 4234.464 | F24: 1310.928 | G24: 955.848 | H24: 1381.056 | I24: 131.256 | J24: -14.568
A25: =_xlfn.IFNA(VLOOKUP(B25,Mapping!C:D,2,FALSE),C25) -> 1190064722 | B25: =C25&D25 -> 1190064722AMV | C25: 1190064722 | D25: AMV | E25: 7 | F25: 7 | G25: 11 | H25: 145
A26: =_xlfn.IFNA(VLOOKUP(B26,Mapping!C:D,2,FALSE),C26) -> 1190064722 | B26: =C26&D26 -> 1190064722LPD | C26: 1190064722 | D26: LPD | G26: 12 | H26: 12 | I26: 12
A27: =_xlfn.IFNA(VLOOKUP(B27,Mapping!C:D,2,FALSE),C27) -> 1190064722 | B27: =C27&D27 -> 1190064722AJA | C27: 1190064722 | D27: AJA | F27: 1 | G27: 4 | H27: 28 | N27: -18.1 | O27: -0.2
A28: =_xlfn.IFNA(VLOOKUP(B28,Mapping!C:D,2,FALSE),C28) -> 5490000721 | B28: =C28&D28 -> 5490000721AJ | C28: 5490000721 | D28: AJ | E28: 373.2 | F28: 1183.656 | G28: 547.6 | H28: 1214.4 | I28: 1178.7 | J28: 682.8 | K28: 1117.9 | L28: 2231.6 | M28: 2499.2 | N28: 729.6 | O28: 2481.6 | P28: 1599.2
A29: =_xlfn.IFNA(VLOOKUP(B29,Mapping!C:D,2,FALSE),C29) -> 5490000721 | B29: =C29&D29 -> 5490000721RD | C29: 5490000721 | D29: RD | E29: 386.8 | F29: 642.9 | G29: 320.38 | H29: 541.53 | I29: 370.2 | J29: 495.5 | K29: 561 | L29: 1364.665 | M29: 1152.8 | N29: 219.2 | O29: 602 | P29: 672.8
A30: =_xlfn.IFNA(VLOOKUP(B30,Mapping!C:D,2,FALSE),C30) -> 5490000721 | B30: =C30&D30 -> 5490000721FP | C30: 5490000721 | D30: FP | E30: 218.88 | F30: 817.452 | G30: 189.312 | H30: 386.604 | I30: 613.398 | J30: 540.252 | K30: 541.848 | L30: 570.18 | M30: 525.072 | N30: 199.776
A31: =_xlfn.IFNA(VLOOKUP(B31,Mapping!C:D,2,FALSE),C31) -> 5490000721 | B31: =C31&D31 -> 5490000721BD | C31: 5490000721 | D31: BD | E31: 166 | F31: 150.81667 | G31: 214 | H31: 200 | I31: 219.8 | J31: 173 | K31: 296.5 | L31: 223.58333 | M31: 282 | N31: 101.16667 | O31: 267.83333 | P31: 213
A32: =_xlfn.IFNA(VLOOKUP(B32,Mapping!C:D,2,FALSE),C32) -> 5490000721 | B32: =C32&D32 -> 5490000721YY | C32: 5490000721 | D32: YY | E32: 152 | F32: 266.83333 | G32: 154.94167 | H32: 92.183333 | I32: 309.05833 | J32: 102.5 | K32: 248.61667 | L32: 211.84444 | M32: 346.05556 | N32: 15.791667 | O32: 179.62222 | P32: 175.56944
A33: =_xlfn.IFNA(VLOOKUP(B33,Mapping!C:D,2,FALSE),C33) -> 5490000721 | B33: =C33&D33 -> 5490000721TKM | C33: 5490000721 | D33: TKM | E33: 85.2 | F33: 211 | G33: 152.6 | H33: 141.8 | I33: 207.1 | J33: 207.6 | K33: 252.2 | L33: 213.6 | M33: 205.4 | N33: 170.8 | O33: 89.8 | P33: 226.6
A34: =_xlfn.IFNA(VLOOKUP(B34,Mapping!C:D,2,FALSE),C34) -> 5490000721 | B34: =C34&D34 -> 5490000721PDC | C34: 5490000721 | D34: PDC | E34: 114.2598 | F34: 64.53 | G34: 75.4742 | H34: 58.977 | I34: 122.3052 | J34: 81.84 | K34: 159.8926 | L34: 168.804 | M34: 155.7372 | N34: 84.3822 | O34: 45.7307 | P34: 119.6058
A35: =_xlfn.IFNA(VLOOKUP(B35,Mapping!C:D,2,FALSE),C35) -> 5490000721 | B35: =C35&D35 -> 5490000721RM | C35: 5490000721 | D35: RM | E35: 77.5 | F35: 88.74 | G35: 56.08 | H35: 56.5 | I35: 148.08 | J35: 107.6 | K35: 119.6 | L35: 45.73 | M35: 114 | N35: 35 | O35: 53.875 | P35: 51.3
A36: =_xlfn.IFNA(VLOOKUP(B36,Mapping!C:D,2,FALSE),C36) -> 5490000721 | B36: =C36&D36 -> 5490000721RDC | C36: 5490000721 | D36: RDC | E36: 31.68 | F36: 61.92 | G36: 20.16 | H36: 56.16 | I36: 25.2 | J36: 54.72 | K36: 47.52 | L36: 14.4 | M36: 51.84 | N36: 46.08 | O36: 43.2 | P36: 21.6
A37: =_xlfn.IFNA(VLOOKUP(B37,Mapping!C:D,2,FALSE),C37) -> 5490000721 | B37: =C37&D37 -> 5490000721FP | C37: 5490000721 | D37: FP | O37: 316.128 | P37: 126.192
A38: =_xlfn.IFNA(VLOOKUP(B38,Mapping!C:D,2,FALSE),C38) -> 5490000721 | B38: =C38&D38 -> 5490000721AMV | C38: 5490000721 | D38: AMV | E38: 17 | F38: 10 | G38: 45 | I38: 38 | J38: 41 | K38: 24 | L38: 40 | M38: 12 | N38: 4 | O38: 14 | P38: 33
A39: =_xlfn.IFNA(VLOOKUP(B39,Mapping!C:D,2,FALSE),C39) -> 5490000721 | B39: =C39&D39 -> 5490000721RKR | C39: 5490000721 | D39: RKR | E39: 5.4 | F39: 4.59 | G39: 16.2 | H39: 5.4 | I39: 10.8 | J39: 34.2 | K39: 27 | L39: 16.2 | M39: 28.8 | N39: 5.13 | O39: 23.4 | P39: 5.4
A40: =_xlfn.IFNA(VLOOKUP(B40,Mapping!C:D,2,FALSE),C40) -> 5490000721 | B40: =C40&D40 -> 5490000721AJP | C40: 5490000721 | D40: AJP | E40: 10.08 | G40: 10.08 | I40: 20.16 | J40: 10.08 | K40: 20.16 | M40: 30.24 | P40: 30.24
...

Sheet HR Rep
A1: User/Employee ID | B1: Full Name Alt1 (Auto) | C1: Full Name (Auto) | D1: Date of Birth | E1: Age (YY.MM.DD) (Auto) | F1: Employment Details Hire Date/Concurrent Date | G1: Company Company Name | H1: Location Location Name | I1: Division Name | J1: Department Department Name | K1: Section Section Name | L1: Job Title | M1: Position Name (TH) | N1: Position Level | O1: Company E-mail (Personnel) Email Information Company Email | P1: Company E-mail (Center) Email Information Company Email | Q1: Job Grade | R1: Cost Centre | S1: Employment Details Service Year | T1: Employment Details Time in Job Grade | U1: Employment Details Retirement Date | V1: *Direct Superior | W1: Department Head of Department | X1: Head of Division | Y1: Last Name | Z1: First Name | AA1: MergeName | AB1: EmpCode | AC1: Direct Sup
A2: 222235 | W2: 222223 | AA2: =Y2&", " &Z2 -> , | AB2: 222235 | AC2: 222223
A3: 066048 | AA3: =Y3&", " &Z3 -> , | AB3: 066048 | AC3: #N/A
A4: 222223 | W4: 222223 | AA4: =Y4&", " &Z4 -> , | AB4: 222223 | AC4: 222222
A5: 222234 | W5: 222234 | AA5: =Y5&", " &Z5 -> , | AB5: 222234 | AC5: 222222
A6: 222238 | W6: 222234 | AA6: =Y6&", " &Z6 -> , | AB6: 222238 | AC6: 222234
A7: 222214 | W7: 222234 | AA7: =Y7&", " &Z7 -> , | AB7: 222214 | AC7: 222236
A8: 222218 | W8: 222234 | AA8: =Y8&", " &Z8 -> , | AB8: 222218 | AC8: 222208
A9: 222229 | W9: 222223 | AA9: =Y9&", " &Z9 -> , | AB9: 222229 | AC9: 222235
A10: 222208 | W10: 222234 | AA10: =Y10&", " &Z10 -> , | AB10: 222208 | AC10: 222234
A11: 222204 | W11: 222223 | AA11: =Y11&", " &Z11 -> , | AB11: 222204 | AC11: 222237
A12: 222203 | W12: 222234 | AA12: =Y12&", " &Z12 -> , | AB12: 222203 | AC12: 222238
A13: 222212 | W13: 222234 | AA13: =Y13&", " &Z13 -> , | AB13: 222212 | AC13: 222208
A14: 222207 | W14: 222223 | AA14: =Y14&", " &Z14 -> , | AB14: 222207 | AC14: 222235
A15: 222219 | W15: 222234 | AA15: =Y15&", " &Z15 -> , | AB15: 222219 | AC15: 222208
... A20: 222209 | W20: 222234 | AA20: =Y20&", " &Z20 -> , | AB20: 222209 | AC20: 222208
A21: 222222 | AA21: =Y21&", " &Z21 -> , | AB21: 222222 | AC21: #N/A
A22: 222215 | W22: 222223 | AA22: =Y22&", " &Z22 -> , | AB22: 222215 | AC22: 222235
A23: 222201 | W23: 222234 | AA23: =Y23&", " &Z23 -> , | AB23: 222201 | AC23: 222238
A24: 222216 | W24: 222223 | AA24: =Y24&", " &Z24 -> , | AB24: 222216 | AC24: 222235
A25: 222213 | W25: 222223 | AA25: =Y25&", " &Z25 -> , | AB25: 222213 | AC25: 222237
A26: 222237 | W26: 222223 | AA26: =Y26&", " &Z26 -> , | AB26: 222237 | AC26: 222223
A27: 222211 | W27: 222234 | AA27: =Y27&", " &Z27 -> , | AB27: 222211 | AC27: 222208
A28: 222236 | W28: 222234 | AA28: =Y28&", " &Z28 -> , | AB28: 222236 | AC28: 222234
A29: 222220 | W29: 222234 | AA29: =Y29&", " &Z29 -> , | AB29: 222220 | AC29: 222238

Sheet Mapping
A1: SalesCode_BI | B1: Product Group | C1: Merge | D1: Salesman Code
A2: 1190064712 | B2: AJ | C2: =A2&B2 -> 1190064712AJ | D2: 5490000711
A3: 1190064712 | B3: AJP | C3: =A3&B3 -> 1190064712AJP | D3: 5490000711
A4: 1190064712 | B4: YY | C4: =A4&B4 -> 1190064712YY | D4: 5490000711
A5: 1190064712 | B5: RKR | C5: =A5&B5 -> 1190064712RKR | D5: 5490000711
A6: 1190064712 | B6: RDC | C6: =A6&B6 -> 1190064712RDC | D6: 5490000705
A7: 1190064712 | B7: RM | C7: =A7&B7 -> 1190064712RM | D7: 5490000705
A8: 1190064712 | B8: ND | C8: =A8&B8 -> 1190064712ND | D8: 5490000705
A9: 1190064712 | B9: RD | C9: =A9&B9 -> 1190064712RD | D9: 5490000705
A10: 1190064712 | B10: BD | C10: =A10&B10 -> 1190064712BD | D10: 5490000714
A11: 1190064712 | B11: PDC | C11: =A11&B11 -> 1190064712PDC | D11: 5490000714
A12: 1190064712 | B12: TKM | C12: =A12&B12 -> 1190064712TKM | D12: 5490000714
A13: 5490000704 | B13: YY | C13: =A13&B13 -> 5490000704YY | D13: 5490000702
... A25: 5490000704 | B25: PDC | C25: =A25&B25 -> 5490000704PDC | D25: 5490000708

Sheet 2) หลักการคำนวน Table
A1: Sales | B1: Standard | C1: Money and Goal | L1: Product
C2: 0.9 | D2: 0.95 | E2: 1 | F2: 1.03 | G2: 1.08 | H2: 1.1 | I2: 1.15 | J2: 1.2 | K2: 1.3
A3: Team | B3: Incentive | C3: 0.9 | D3: 0.95 | E3: 1 | F3: 1.03 | G3: 1.06 | H3: 1.1 | I3: 1.15 | J3: 1.2 | K3: 20 | L3: AJ | M3: RD | N3: BD | O3: AJP | P3: RDC | Q3: RM | R3: ND | S3: YY | T3: PDC | U3: TKM | V3: RKR | W3: AMV | X3: AJA | Y3: FP | Z3: QM
A4: 5490000718 | B4: 4000 | C4: =($B4*C$2) -> 3600 | D4: =($B4*D$2) -> 3800 | E4: =($B4*E$2) -> 4000 | F4: =($B4*F$2) -> 4120 | G4: =($B4*G$2) -> 4320 | H4: =($B4*H$2) -> 4400 | I4: =($B4*I$2) -> 4600 | J4: =($B4*J$2) -> 4800 | K4: =($B4*K$2) -> 5200 | L4: 0.033333333 | M4: 0.055555556 | N4: 0.11111111 | O4: 0.055555556 | P4: 0.11111111 | Q4: 0.11111111 | S4: 0.11111111 | T4: 0.16666667 | U4: 0.044444444 | V4: 0.044444444 | W4: 0.022222222 | X4: 0.011111111 | Y4: 0.11111111 | Z4: 0.011111111
A5: 5490000706 | B5: 4000 | C5: =($B5*C$2) -> 3600 | D5: =($B5*D$2) -> 3800 | E5: =($B5*E$2) -> 4000 | F5: =($B5*F$2) -> 4120 | G5: =($B5*G$2) -> 4320 | H5: =($B5*H$2) -> 4400 | I5: =($B5*I$2) -> 4600 | J5: =($B5*J$2) -> 4800 | K5: =($B5*K$2) -> 5200 | L5: 0.03030303 | M5: 0.050505051 | N5: 0.1010101 | O5: 0.050505051 | P5: 0.1010101 | Q5: 0.1010101 | R5: 0.1010101 | S5: 0.1010101 | T5: 0.15151515 | U5: 0.04040404 | V5: 0.04040404 | W5: 0.02020202 | Y5: 0.1010101 | Z5: 0.01
A6: 5490000707 | B6: 5000 | C6: =($B6*C$2) -> 4500 | D6: =($B6*D$2) -> 4750 | E6: =($B6*E$2) -> 5000 | F6: =($B6*F$2) -> 5150 | G6: =($B6*G$2) -> 5400 | H6: =($B6*H$2) -> 5500 | I6: =($B6*I$2) -> 5750 | J6: =($B6*J$2) -> 6000 | K6: =($B6*K$2) -> 6500 | L6: 0.034883721 | M6: 0.058139535 | N6: 0.11627907 | O6: 0.058139535 | P6: 0.11627907 | Q6: 0.11627907 | R6: 0.11627907 | S6: 0.11627907 | T6: 0.1744186 | U6: 0.046511628 | V6: 0.046511628
A7: 5490000701 | B7: 5000 | C7: =($B7*C$2) -> 4500 | D7: =($B7*D$2) -> 4750 | E7: =($B7*E$2) -> 5000 | F7: =($B7*F$2) -> 5150 | G7: =($B7*G$2) -> 5400 | H7: =($B7*H$2) -> 5500 | I7: =($B7*I$2) -> 5750 | J7: =($B7*J$2) -> 6000 | K7: =($B7*K$2) -> 6500 | L7: 0.030927835 | M7: 0.051546392 | N7: 0.10309278 | O7: 0.051546392 | P7: 0.10309278 | Q7: 0.10309278 | R7: 0.10309278 | S7: 0.10309278 | T7: 0.15463918 | U7: 0.041237113 | V7: 0.041237113 | Y7: 0.10309278 | Z7: 0.010309278
A8: 5490000721 | B8: 5000 | C8: =($B8*C$2) -> 4500 | D8: =($B8*D$2) -> 4750 | E8: =($B8*E$2) -> 5000 | F8: =($B8*F$2) -> 5150 | G8: =($B8*G$2) -> 5400 | H8: =($B8*H$2) -> 5500 | I8: =($B8*I$2) -> 5750 | J8: =($B8*J$2) -> 6000 | K8: =($B8*K$2) -> 6500 | L8: 0.033333333 | M8: 0.055555556 | N8: 0.11111111 | O8: 0.055555556 | P8: 0.11111111 | Q8: 0.11111111 | S8: 0.11111111 | T8: 0.16666667 | U8: 0.044444444 | V8: 0.044444444 | W8: 0.022222222 | X8: 0.011111111 | Y8: 0.11111111 | Z8: 0.011111111
A9: 5490000719 | B9: 5000 | C9: =($B9*C$2) -> 4500 | D9: =($B9*D$2) -> 4750 | E9: =($B9*E$2) -> 5000 | F9: =($B9*F$2) -> 5150 | G9: =($B9*G$2) -> 5400 | H9: =($B9*H$2) -> 5500 | I9: =($B9*I$2) -> 5750 | J9: =($B9*J$2) -> 6000 | K9: =($B9*K$2) -> 6500 | L9: 0.034883721 | M9: 0.058139535 | N9: 0.11627907 | O9: 0.058139535 | P9: 0.11627907 | Q9: 0.11627907 | R9: 0.11627907 | S9: 0.11627907 | T9: 0.1744186 | U9: 0.046511628 | V9: 0.046511628
A10: 222208 | B10: 5000 | C10: =($B10*C$2) -> 4500 | D10: =($B10*D$2) -> 4750 | E10: =($B10*E$2) -> 5000 | F10: =($B10*F$2) -> 5150 | G10: =($B10*G$2) -> 5400 | H10: =($B10*H$2) -> 5500 | I10: =($B10*I$2) -> 5750 | J10: =($B10*J$2) -> 6000 | K10: =($B10*K$2) -> 6500 | L10: 0.03 | M10: 0.05 | N10: 0.1 | O10: 0.05 | P10: 0.1 | Q10: 0.1 | R10: 0.1 | S10: 0.1 | T10: 0.15 | U10: 0.04 | V10: 0.04 | W10: 0.02 | X10: 0.01 | Y10: 0.1 | Z10: 0.01
A11: 5490000725 | B11: 4000 | C11: =($B11*C$2) -> 3600 | D11: =($B11*D$2) -> 3800 | E11: =($B11*E$2) -> 4000 | F11: =($B11*F$2) -> 4120 | G11: =($B11*G$2) -> 4320 | H11: =($B11*H$2) -> 4400 | I11: =($B11*I$2) -> 4600 | J11: =($B11*J$2) -> 4800 | K11: =($B11*K$2) -> 5200 | L11: 0.056179775 | M11: 0.056179775 | N11: 0.16853933 | O11: 0.056179775 | P11: 0.11235955 | Q11: 0.11235955 | S11: 0.15730337 | T11: 0.16853933 | U11: 0.056179775 | V11: 0.056179775
A12: 5490000702 | B12: 4000 | C12: =($B12*C$2) -> 3600 | D12: =($B12*D$2) -> 3800 | E12: =($B12*E$2) -> 4000 | F12: =($B12*F$2) -> 4120 | G12: =($B12*G$2) -> 4320 | H12: =($B12*H$2) -> 4400 | I12: =($B12*I$2) -> 4600 | J12: =($B12*J$2) -> 4800 | K12: =($B12*K$2) -> 5200 | S12: 0.92307692 | X12: 0.076923077
A13: 5490000708 | B13: 4000 | C13: =($B13*C$2) -> 3600 | D13: =($B13*D$2) -> 3800 | E13: =($B13*E$2) -> 4000 | F13: =($B13*F$2) -> 4120 | G13: =($B13*G$2) -> 4320 | H13: =($B13*H$2) -> 4400 | I13: =($B13*I$2) -> 4600 | J13: =($B13*J$2) -> 4800 | K13: =($B13*K$2) -> 5200 | N13: 0.5 | T13: 0.5
A14: 5490000704 | B14: 5000 | C14: =($B14*C$2) -> 4500 | D14: =($B14*D$2) -> 4750 | E14: =($B14*E$2) -> 5000 | F14: =($B14*F$2) -> 5150 | G14: =($B14*G$2) -> 5400 | H14: =($B14*H$2) -> 5500 | I14: =($B14*I$2) -> 5750 | J14: =($B14*J$2) -> 6000 | K14: =($B14*K$2) -> 6500 | L14: 0.053571429 | M14: 0.089285714 | O14: 0.089285714 | P14: 0.19642857 | Q14: 0.21428571 | R14: 0.17857143 | U14: 0.089285714 | V14: 0.089285714
A15: 222238 | B15: 5000 | C15: =($B15*C$2) -> 4500 | D15: =($B15*D$2) -> 4750 | E15: =($B15*E$2) -> 5000 | F15: =($B15*F$2) -> 5150 | G15: =($B15*G$2) -> 5400 | H15: =($B15*H$2) -> 5500 | I15: =($B15*I$2) -> 5750 | J15: =($B15*J$2) -> 6000 | K15: =($B15*K$2) -> 6500 | L15: 0.03030303 | M15: 0.050505051 | N15: 0.15151515 | O15: 0.050505051 | P15: 0.11111111 | Q15: 0.12121212 | R15: 0.1010101 | S15: 0.12121212 | T15: 0.15151515 | U15: 0.050505051 | V15: 0.050505051 | X15: 0.01010101
A16: 5490000713 | B16: 5000 | C16: =($B16*C$2) -> 4500 | D16: =($B16*D$2) -> 4750 | E16: =($B16*E$2) -> 5000 | F16: =($B16*F$2) -> 5150 | G16: =($B16*G$2) -> 5400 | H16: =($B16*H$2) -> 5500 | I16: =($B16*I$2) -> 5750 | J16: =($B16*J$2) -> 6000 | K16: =($B16*K$2) -> 6500 | N16: 0.26666667 | S16: 0.22222222 | T16: 0.26666667 | Y16: 0.22222222 | Z16: 0.022222222
A17: 5490000709 | B17: 5000 | C17: =($B17*C$2) -> 4500 | D17: =($B17*D$2) -> 4750 | E17: =($B17*E$2) -> 5000 | F17: =($B17*F$2) -> 5150 | G17: =($B17*G$2) -> 5400 | H17: =($B17*H$2) -> 5500 | I17: =($B17*I$2) -> 5750 | J17: =($B17*J$2) -> 6000 | K17: =($B17*K$2) -> 6500 | L17: 0.055555556 | M17: 0.092592593 | O17: 0.092592593 | P17: 0.18518519 | Q17: 0.2037037 | R17: 0.18518519 | U17: 0.074074074 | V17: 0.074074074 | W17: 0.037037037
A18: 5490000703 | B18: 5000 | C18: =($B18*C$2) -> 4500 | D18: =($B18*D$2) -> 4750 | E18: =($B18*E$2) -> 5000 | F18: =($B18*F$2) -> 5150 | G18: =($B18*G$2) -> 5400 | H18: =($B18*H$2) -> 5500 | I18: =($B18*I$2) -> 5750 | J18: =($B18*J$2) -> 6000 | K18: =($B18*K$2) -> 6500 | N18: 0.35294118 | S18: 0.29411765 | T18: 0.35294118
A19: 5490000717 | B19: 5000 | C19: =($B19*C$2) -> 4500 | D19: =($B19*D$2) -> 4750 | E19: =($B19*E$2) -> 5000 | F19: =($B19*F$2) -> 5150 | G19: =($B19*G$2) -> 5400 | H19: =($B19*H$2) -> 5500 | I19: =($B19*I$2) -> 5750 | J19: =($B19*J$2) -> 6000 | K19: =($B19*K$2) -> 6500 | L19: 0.057692308 | M19: 0.096153846 | O19: 0.096153846 | P19: 0.19230769 | Q19: 0.21153846 | R19: 0.19230769 | U19: 0.076923077 | V19: 0.076923077
A20: 222237 | B20: 5000 | C20: =($B20*C$2) -> 4500 | D20: =($B20*D$2) -> 4750 | E20: =($B20*E$2) -> 5000 | F20: =($B20*F$2) -> 5150 | G20: =($B20*G$2) -> 5400 | H20: =($B20*H$2) -> 5500 | I20: =($B20*I$2) -> 5750 | J20: =($B20*J$2) -> 6000 | K20: =($B20*K$2) -> 6500 | L20: 0.03030303 | M20: 0.050505051 | N20: 0.12121212 | O20: 0.050505051 | P20: 0.1010101 | Q20: 0.11111111 | R20: 0.1010101 | S20: 0.1010101 | T20: 0.12121212 | U20: 0.04040404 | V20: 0.04040404 | W20: 0.02020202 | Y20: 0.1010101 | Z20: 0.01010101
A21: 5490000710 | B21: 5000 | C21: =($B21*C$2) -> 4500 | D21: =($B21*D$2) -> 4750 | E21: =($B21*E$2) -> 5000 | F21: =($B21*F$2) -> 5150 | G21: =($B21*G$2) -> 5400 | H21: =($B21*H$2) -> 5500 | I21: =($B21*I$2) -> 5750 | J21: =($B21*J$2) -> 6000 | K21: =($B21*K$2) -> 6500 | W21: 0.7 | X21: 0.3
A22: 222236 | B22: 5000 | C22: =($B22*C$2) -> 4500 | D22: =($B22*D$2) -> 4750 | E22: =($B22*E$2) -> 5000 | F22: =($B22*F$2) -> 5150 | G22: =($B22*G$2) -> 5400 | H22: =($B22*H$2) -> 5500 | I22: =($B22*I$2) -> 5750 | J22: =($B22*J$2) -> 6000 | K22: =($B22*K$2) -> 6500 | W22: 0.7 | X22: 0.3
A23: 5490000720 | B23: 5500 | C23: =($B23*C$2) -> 4950 | D23: =($B23*D$2) -> 5225 | E23: =($B23*E$2) -> 5500 | F23: =($B23*F$2) -> 5665 | G23: =($B23*G$2) -> 5940 | H23: =($B23*H$2) -> 6050 | I23: =($B23*I$2) -> 6325 | J23: =($B23*J$2) -> 6600 | K23: =($B23*K$2) -> 7150 | L23: 0.031578947 | M23: 0.031578947 | N23: 0.15789474 | O23: 0.052631579 | P23: 0.11578947 | Q23: 0.10526316 | R23: 0.12631579 | S23: 0.12631579 | T23: 0.15789474 | U23: 0.052631579 | V23: 0.042105263
A24: 5490000714 | B24: 5500 | C24: =($B24*C$2) -> 4950 | D24: =($B24*D$2) -> 5225 | E24: =($B24*E$2) -> 5500 | F24: =($B24*F$2) -> 5665 | G24: =($B24*G$2) -> 5940 | H24: =($B24*H$2) -> 6050 | I24: =($B24*I$2) -> 6325 | J24: =($B24*J$2) -> 6600 | K24: =($B24*K$2) -> 7150 | N24: 0.42857143 | T24: 0.42857143 | U24: 0.14285714
A25: 5490000705 | B25: 5500 | C25: =($B25*C$2) -> 4950 | D25: =($B25*D$2) -> 5225 | E25: =($B25*E$2) -> 5500 | F25: =($B25*F$2) -> 5665 | G25: =($B25*G$2) -> 5940 | H25: =($B25*H$2) -> 6050 | I25: =($B25*I$2) -> 6325 | J25: =($B25*J$2) -> 6600 | K25: =($B25*K$2) -> 7150 | M25: 0.083333333 | P25: 0.30555556 | Q25: 0.27777778 | R25: 0.33333333
A26: 5490000711 | B26: 5500 | C26: =($B26*C$2) -> 4950 | D26: =($B26*D$2) -> 5225 | E26: =($B26*E$2) -> 5500 | F26: =($B26*F$2) -> 5665 | G26: =($B26*G$2) -> 5940 | H26: =($B26*H$2) -> 6050 | I26: =($B26*I$2) -> 6325 | J26: =($B26*J$2) -> 6600 | K26: =($B26*K$2) -> 7150 | L26: 0.125 | O26: 0.20833333 | S26: 0.5 | V26: 0.16666667
A27: 222235 | B27: 6000 | C27: =($B27*C$2) -> 5400 | D27: =($B27*D$2) -> 5700 | E27: =($B27*E$2) -> 6000 | F27: =($B27*F$2) -> 6180 | G27: =($B27*G$2) -> 6480 | H27: =($B27*H$2) -> 6600 | I27: =($B27*I$2) -> 6900 | J27: =($B27*J$2) -> 7200 | K27: =($B27*K$2) -> 7800 | L27: 0.031578947 | M27: 0.031578947 | N27: 0.15789474 | O27: 0.052631579 | P27: 0.11578947 | Q27: 0.10526316 | R27: 0.12631579 | S27: 0.12631579 | T27: 0.15789474 | U27: 0.052631579 | V27: 0.042105263
A28: 222234 | B28: 6000 | C28: =($B28*C$2) -> 5400 | D28: =($B28*D$2) -> 5700 | E28: =($B28*E$2) -> 6000 | F28: =($B28*F$2) -> 6180 | G28: =($B28*G$2) -> 6480 | H28: =($B28*H$2) -> 6600 | I28: =($B28*I$2) -> 6900 | J28: =($B28*J$2) -> 7200 | K28: =($B28*K$2) -> 7800 | L28: 0.1719 | M28: 0.1257 | N28: 0.3654 | O28: 0.0203 | P28: 0.0133 | Q28: 0.0204 | R28: 0.0031 | S28: 0.2008 | T28: 0.056 | U28: 0.012 | V28: 0.0052 | W28: 0.0033 | X28: 0.0001 | Y28: 0.0024 | Z28: 0.0001
A29: 222223 | B29: 6000 | C29: =($B29*C$2) -> 5400 | D29: =($B29*D$2) -> 5700 | E29: =($B29*E$2) -> 6000 | F29: =($B29*F$2) -> 6180 | G29: =($B29*G$2) -> 6480 | H29: =($B29*H$2) -> 6600 | I29: =($B29*I$2) -> 6900 | J29: =($B29*J$2) -> 7200 | K29: =($B29*K$2) -> 7800 | L29: 0.21112111 | M29: 0.28692869 | N29: 0.20632063 | O29: 0.02170217 | P29: 0.0090009001 | Q29: 0.0270027 | R29: 0.00380038 | S29: 0.13521352 | T29: 0.079707971 | U29: 0.01450145 | V29: 0.00410041 | W29: 0.00010001 | Y29: 0.00040004 | Z29: 0.00010001
A30: 222222 | B30: 6000 | C30: =($B30*C$2) -> 5400 | D30: =($B30*D$2) -> 5700 | E30: =($B30*E$2) -> 6000 | F30: =($B30*F$2) -> 6180 | G30: =($B30*G$2) -> 6480 | H30: =($B30*H$2) -> 6600 | I30: =($B30*I$2) -> 6900 | J30: =($B30*J$2) -> 7200 | K30: =($B30*K$2) -> 7800 | L30: 0.03 | M30: 0.03 | N30: 0.1 | O30: 0.05 | P30: 0.1 | Q30: 0.1 | R30: 0.1 | S30: 0.08 | T30: 0.07 | U30: 0.03 | V30: 0.03 | W30: 0.09 | X30: 0.08 | Y30: 0.1 | Z30: 0.01
P40: 0.05
P41: 0.05
P42: 0.12
P43: 0.12
P44: 0.12
P45: 0.12
P46: 0.05
P47: 0.14
P48: 0.13
P49: 0.05
...

Sheet 3)Target & Cal_Staff
A1: Direct Sup. | D1: Target | P1: Actual | AB1: Percent (Actual vs Target) | AN1: Percent (Round) (Actual vs Target) | AZ1: Incentive
D2: 2 | E2: 3 | F2: 4 | G2: 5 | H2: 6 | I2: 7 | J2: 8 | K2: 9 | L2: 10 | M2: 11 | N2: 12 | O2: 13 | P2: 2 | Q2: 3 | R2: 4 | S2: 5 | T2: 6 | U2: 7 | V2: 8 | W2: 9 | X2: 10 | Y2: 11 | Z2: 12 | AA2: 13 | AB2: 2 | AC2: 3 | AD2: 4 | AE2: 5 | AF2: 6 | AG2: 7 | AH2: 8 | AI2: 9 | AJ2: 10 | AK2: 11 | AL2: 12 | AM2: 13 | AN2: 2 | AO2: 3 | AP2: 4 | AQ2: 5 | AR2: 6 | AS2: 7 | AT2: 8 | AU2: 9 | AV2: 10 | AW2: 11 | AX2: 12 | AY2: 13 | AZ2: 2 | BA2: 3 | BB2: 4 | BC2: 5 | BD2: 6 | BE2: 7 | BF2: 8 | BG2: 9 | BH2: 10 | BI2: 11 | BJ2: 12 | BK2: 13
A3: DirectSupCode | B3: Product | C3: Team | D3: Apr_T | E3: May_T | F3: Jun_T | G3: Jul_T | H3: Aug_T | I3: Sep_T | J3: Oct_T | K3: Nov_T | L3: Dec_T | M3: Jan_T | N3: Feb_T | O3: Mar_T | P3: Apr_A | Q3: May_A | R3: Jun_A | S3: Jul_A | T3: Aug_A | U3: Sep_A | V3: Oct_A | W3: Nov_A | X3: Dec_A | Y3: Jan_A | Z3: Feb_A | AA3: Mar_A | AB3: Apr_P | AC3: May_P | AD3: Jun_P | AE3: Jul_P | AF3: Aug_P | AG3: Sep_P | AH3: Oct_P | AI3: Nov_P | AJ3: Dec_P | AK3: Jan_P | AL3: Feb_P | AM3: Mar_P | AN3: Apr_I | AO3: May_I | AP3: Jun_I | AQ3: Jul_I | AR3: Aug_I | AS3: Sep_I | AT3: Oct_I | AU3: Nov_I | AV3: Dec_I | AW3: Jan_I | AX3: Feb_I | AY3: Mar_I | AZ3: Apr_I | BA3: May_I | BB3: Jun_I | BC3: Jul_I | BD3: Aug_I | BE3: Sep_I | BF3: Oct_I | BG3: Nov_I | BH3: Dec_I | BI3: Jan_I | BJ3: Feb_I | BK3: Mar_I | BM3: Emp Code | BN3: Incentive
