Workbook

Sheet M_Month
A1: sales incentive ของเดือน | B1: รอบการจ่าย Incentive (Variable) | C1: รอบการจ่าย Incentive (Fixed) | D1: Default column
A2: Apr-26 | B2: Jun-26 | C2: May-26 | D2: 1
A3: May-26 | B3: Jul-26 | C3: Jun-26 | D3: 2
A4: Jun-26 | B4: Aug-26 | C4: Jul-26 | D4: 3
A5: Jul-26 | B5: Sep-26 | C5: Aug-26 | D5: 4
A6: Aug-26 | B6: Oct-26 | C6: Sep-26 | D6: 5
A7: Sep-26 | B7: Nov-26 | C7: Oct-26 | D7: 6
A8: Oct-26 | B8: Dec-26 | C8: Nov-26 | D8: 7
A9: Nov-26 | B9: Jan-27 | C9: Dec-26 | D9: 8
A10: Dec-26 | B10: Feb-27 | C10: Jan-27 | D10: 9
A11: Jan-27 | B11: Mar-27 | C11: Feb-27 | D11: 10
A12: Feb-27 | B12: Apr-27 | C12: Mar-27 | D12: 11
A13: Mar-27 | B13: May-27 | C13: Apr-27 | D13: 12

Sheet T_SectAbove
A1: Position Level | B1: Compensation rate
A2: Division Manager | B2: 5000
A3: Department Manager | B3: 5000
A4: Section Manager | B4: 4000
A5: Associate Director | B5: 6000
A6: AAA | B6: 7000
A7: Maintain ที่ระบบนี้

Sheet Period
A1: sales incentive ของเดือน | B1: รอบการจ่าย Incentive (Variable) | C1: รอบการจ่าย Incentive (Fixed) | D1: Default column
A2: May-26 | B2: =VLOOKUP(A2,M_Month!A:B,2,FALSE) -> Jul-26 | C2: =VLOOKUP(A2,M_Month!A:D,3,FALSE) -> Jun-26 | D2: =VLOOKUP(A2,M_Month!A:E,4,FALSE) -> 2

Sheet ASTBase
A1: เดือน | B1: ปี | C1: Area | D1: Depot | E1: Salesman Code | F1: รหัสพนักงาน (พนักงานขาย) | G1: ชื่อ - นามสกุล (พนักงานขาย) | H1: รหัสพนักงาน (พนักงานผู้ช่วยขาย) | I1: ชื่อ - นามสกุล (พนักงานผู้ช่วยขาย) | J1: สถานะพนักงาน (พนักงานผู้ช่วยขาย) | K1: ทีม | L1: ทะเบียนรถ | M1: ประเภทรถยนต์ | N1: หมายเหตุ | O1: ตรวจสอบ | P1: Salesman Code | Q1: DirectSupCode | R1: DeptMgQode | S1: DivMgQode
A2: May | B2: 2026 | F2: 000002 | P2: =E2 -> 0 | Q2: =VLOOKUP(F2,'HR Rep'!A:AC,29,FALSE) -> 000001 | R2: =VLOOKUP(F2,'HR Rep'!A:AC,23,FALSE) -> 0 | S2: =VLOOKUP(F2,'HR Rep'!A:AC,24,FALSE) -> 0
A3: May | B3: 2026 | C3: BANGKOK | F3: 000003 | P3: =E3 -> 0 | Q3: =VLOOKUP(F3,'HR Rep'!A:AC,29,FALSE) -> 000002 | R3: =VLOOKUP(F3,'HR Rep'!A:AC,23,FALSE) -> 000003 | S3: =VLOOKUP(F3,'HR Rep'!A:AC,24,FALSE) -> 000002
A4: May | B4: 2026 | C4: BANGKOK | D4: Bangpoo | E4: 110000 | F4: 000004 | P4: =E4 -> 110000 | Q4: =VLOOKUP(F4,'HR Rep'!A:AC,29,FALSE) -> 000003 | R4: =VLOOKUP(F4,'HR Rep'!A:AC,23,FALSE) -> 000003 | S4: =VLOOKUP(F4,'HR Rep'!A:AC,24,FALSE) -> 000002
A5: May | B5: 2026 | C5: BANGKOK | D5: Bangpoo | E5: 110001 | F5: 000005 | P5: =E5 -> 110001 | Q5: =VLOOKUP(F5,'HR Rep'!A:AC,29,FALSE) -> 000004 | R5: =VLOOKUP(F5,'HR Rep'!A:AC,23,FALSE) -> 000003 | S5: =VLOOKUP(F5,'HR Rep'!A:AC,24,FALSE) -> 000002
A6: May | B6: 2026 | C6: BANGKOK | D6: Bangpoo | E6: 110002 | F6: 000006 | P6: =E6 -> 110002 | Q6: =VLOOKUP(F6,'HR Rep'!A:AC,29,FALSE) -> 000004 | R6: =VLOOKUP(F6,'HR Rep'!A:AC,23,FALSE) -> 000003 | S6: =VLOOKUP(F6,'HR Rep'!A:AC,24,FALSE) -> 000002
A7: May | B7: 2026 | C7: BANGKOK | D7: Bangpoo | E7: 110003 | F7: 000007 | P7: =E7 -> 110003 | Q7: =VLOOKUP(F7,'HR Rep'!A:AC,29,FALSE) -> 000004 | R7: =VLOOKUP(F7,'HR Rep'!A:AC,23,FALSE) -> 000003 | S7: =VLOOKUP(F7,'HR Rep'!A:AC,24,FALSE) -> 000002
A8: May | B8: 2026 | C8: BANGKOK | D8: Nonthaburi | E8: 120000 | F8: 000008 | P8: =E8 -> 120000 | Q8: =VLOOKUP(F8,'HR Rep'!A:AC,29,FALSE) -> 000003 | R8: =VLOOKUP(F8,'HR Rep'!A:AC,23,FALSE) -> 000003 | S8: =VLOOKUP(F8,'HR Rep'!A:AC,24,FALSE) -> 000002
A9: May | B9: 2026 | C9: BANGKOK | D9: Nonthaburi | E9: 120001 | F9: 000009 | P9: =E9 -> 120001 | Q9: =VLOOKUP(F9,'HR Rep'!A:AC,29,FALSE) -> 000008 | R9: =VLOOKUP(F9,'HR Rep'!A:AC,23,FALSE) -> 000003 | S9: =VLOOKUP(F9,'HR Rep'!A:AC,24,FALSE) -> 000002
A10: May | B10: 2026 | C10: BANGKOK | D10: Nonthaburi | E10: 120002 | F10: 000010 | P10: =E10 -> 120002 | Q10: =VLOOKUP(F10,'HR Rep'!A:AC,29,FALSE) -> 000008 | R10: =VLOOKUP(F10,'HR Rep'!A:AC,23,FALSE) -> 000003 | S10: =VLOOKUP(F10,'HR Rep'!A:AC,24,FALSE) -> 000002
A11: May | B11: 2026 | C11: BANGKOK | D11: Pathum Thani | E11: 130000 | F11: 000011 | P11: =E11 -> 130000 | Q11: =VLOOKUP(F11,'HR Rep'!A:AC,29,FALSE) -> 000003 | R11: =VLOOKUP(F11,'HR Rep'!A:AC,23,FALSE) -> 000003 | S11: =VLOOKUP(F11,'HR Rep'!A:AC,24,FALSE) -> 000002
A12: May | B12: 2026 | C12: BANGKOK | D12: Pathum Thani | E12: 130001 | F12: 000012 | P12: =E12 -> 130001 | Q12: =VLOOKUP(F12,'HR Rep'!A:AC,29,FALSE) -> 000011 | R12: =VLOOKUP(F12,'HR Rep'!A:AC,23,FALSE) -> 000003 | S12: =VLOOKUP(F12,'HR Rep'!A:AC,24,FALSE) -> 000002
A13: May | B13: 2026 | C13: BANGKOK | D13: Pathum Thani | E13: 130002 | F13: 000013 | P13: =E13 -> 130002 | Q13: =VLOOKUP(F13,'HR Rep'!A:AC,29,FALSE) -> 000011 | R13: =VLOOKUP(F13,'HR Rep'!A:AC,23,FALSE) -> 000003 | S13: =VLOOKUP(F13,'HR Rep'!A:AC,24,FALSE) -> 000002
A14: May | B14: 2026 | C14: BANGKOK | D14: Pathum Thani | E14: 130003 | F14: 000014 | P14: =E14 -> 130003 | Q14: =VLOOKUP(F14,'HR Rep'!A:AC,29,FALSE) -> 000011 | R14: =VLOOKUP(F14,'HR Rep'!A:AC,23,FALSE) -> 000003 | S14: =VLOOKUP(F14,'HR Rep'!A:AC,24,FALSE) -> 000002
A15: May | B15: 2026 | C15: BANGKOK | D15: Pattanakan | E15: 140000 | F15: 000015 | P15: =E15 -> 140000 | Q15: =VLOOKUP(TEXT(F15,"0"),'HR Rep'!A:AC,29,FALSE) -> #N/A | R15: =VLOOKUP(F15,'HR Rep'!A:AC,23,FALSE) -> 000003 | S15: =VLOOKUP(TEXT(F15,"0"),'HR Rep'!A:AC,24,FALSE) -> #N/A
A16: May | B16: 2026 | C16: BANGKOK | D16: Pattanakan | E16: 140001 | F16: 000016 | P16: =E16 -> 140001 | Q16: =VLOOKUP(F16,'HR Rep'!A:AC,29,FALSE) -> 000015 | R16: =VLOOKUP(F16,'HR Rep'!A:AC,23,FALSE) -> 000003 | S16: =VLOOKUP(F16,'HR Rep'!A:AC,24,FALSE) -> 000002
A17: May | B17: 2026 | C17: BANGKOK | D17: Pattanakan | E17: 140002 | F17: 000017 | P17: =E17 -> 140002 | Q17: =VLOOKUP(F17,'HR Rep'!A:AC,29,FALSE) -> 000015 | R17: =VLOOKUP(F17,'HR Rep'!A:AC,23,FALSE) -> 000003 | S17: =VLOOKUP(F17,'HR Rep'!A:AC,24,FALSE) -> 000002
A18: May | B18: 2026 | C18: BANGKOK | D18: Pattanakan | E18: 140003 | F18: 000018 | P18: =E18 -> 140003 | Q18: =VLOOKUP(F18,'HR Rep'!A:AC,29,FALSE) -> 000015 | R18: =VLOOKUP(F18,'HR Rep'!A:AC,23,FALSE) -> 000003 | S18: =VLOOKUP(F18,'HR Rep'!A:AC,24,FALSE) -> 000002
A19: May | B19: 2026 | C19: BANGKOK | D19: Ram Indra | E19: 150000 | F19: 000019 | P19: =E19 -> 150000 | Q19: =VLOOKUP(F19,'HR Rep'!A:AC,29,FALSE) -> 000003 | R19: =VLOOKUP(F19,'HR Rep'!A:AC,23,FALSE) -> 000003 | S19: =VLOOKUP(F19,'HR Rep'!A:AC,24,FALSE) -> 000002
A20: May | B20: 2026 | C20: BANGKOK | D20: Ram Indra | E20: 150001 | F20: 000020 | P20: =E20 -> 150001 | Q20: =VLOOKUP(F20,'HR Rep'!A:AC,29,FALSE) -> 000019 | R20: =VLOOKUP(F20,'HR Rep'!A:AC,23,FALSE) -> 000003 | S20: =VLOOKUP(F20,'HR Rep'!A:AC,24,FALSE) -> 000002
A21: May | B21: 2026 | C21: BANGKOK | D21: Thonburi | E21: 160000 | F21: 000021 | P21: =E21 -> 160000 | Q21: =VLOOKUP(F21,'HR Rep'!A:AC,29,FALSE) -> 000003 | R21: =VLOOKUP(F21,'HR Rep'!A:AC,23,FALSE) -> 000003 | S21: =VLOOKUP(F21,'HR Rep'!A:AC,24,FALSE) -> 000002
A22: May | B22: 2026 | C22: BANGKOK | D22: Thonburi | E22: 160001 | F22: 000022 | P22: =E22 -> 160001 | Q22: =VLOOKUP(F22,'HR Rep'!A:AC,29,FALSE) -> 000021 | R22: =VLOOKUP(F22,'HR Rep'!A:AC,23,FALSE) -> 000003 | S22: =VLOOKUP(F22,'HR Rep'!A:AC,24,FALSE) -> 000002
A23: May | B23: 2026 | C23: BANGKOK | D23: Thonburi | E23: 160002 | F23: 000023 | P23: =E23 -> 160002 | Q23: =VLOOKUP(F23,'HR Rep'!A:AC,29,FALSE) -> 000021 | R23: =VLOOKUP(F23,'HR Rep'!A:AC,23,FALSE) -> 000003 | S23: =VLOOKUP(F23,'HR Rep'!A:AC,24,FALSE) -> 000002

Sheet HR Rep
A1: User/Employee ID | B1: Full Name Alt1 (Auto) | C1: Full Name (Auto) | D1: Date of Birth | E1: Age (YY.MM.DD) (Auto) | F1: Employment Details Hire Date/Concurrent Date | G1: Company Company Name | H1: Location Location Name | I1: Division Name | J1: Department Department Name | K1: Section Section Name | L1: Job Title | M1: Position Name (TH) | N1: Position Level | O1: Company E-mail (Personnel) Email InfoMation Company Email | P1: Company E-mail (Center) Email InfoMation Company Email | Q1: Job Grade | R1: Cost Centre | S1: Employment Details Service Year | T1: Employment Details Time in Job Grade | U1: Employment Details Retirement Date | V1: *Direct Superior | W1: Department Head of Department | X1: Head of Division | Y1: Last Name | Z1: First Name | AA1: MergeName | AB1: EmpCode | AC1: Direct Sup
A2: 000001 | N2: Associate Director | X2: 000002 | AB2: 000001 | AC2: #N/A
A3: 000024 | I3: Traditional Trade | J3: Sales Bangkok | K3: Ram Indra | N3: Staff | W3: 000003 | X3: 000002 | AB3: 000024 | AC3: 000019
A4: 000025 | I4: Traditional Trade | J4: Sales Bangkok | K4: Pattanakan | N4: Staff | W4: 000003 | X4: 000002 | AB4: 000025 | AC4: 000015
A5: 000008 | I5: Traditional Trade | J5: Sales Bangkok | K5: Nonthaburi | N5: Section Manager | W5: 000003 | X5: 000002 | AB5: 000008 | AC5: 000003
A6: 000020 | I6: Traditional Trade | J6: Sales Bangkok | K6: Ram Indra | N6: Supervisor | W6: 000003 | X6: 000002 | AB6: 000020 | AC6: 000019
A7: 000026 | I7: Traditional Trade | J7: Sales Bangkok | K7: Bangpoo | N7: Staff | W7: 000003 | X7: 000002 | AB7: 000026 | AC7: 000004
A8: 000027 | I8: Traditional Trade | J8: Sales Bangkok | K8: Bangpoo | N8: Staff | W8: 000003 | X8: 000002 | AB8: 000027 | AC8: 000004
A9: 000028 | I9: Traditional Trade | J9: Sales Bangkok | K9: Thonburi | N9: Staff | W9: 000003 | X9: 000002 | AB9: 000028 | AC9: 000021
A10: 000029 | I10: Traditional Trade | J10: Sales Bangkok | K10: Thonburi | N10: Staff | W10: 000003 | X10: 000002 | AB10: 000029 | AC10: 000021
A11: 000005 | I11: Traditional Trade | J11: Sales Bangkok | K11: Bangpoo | N11: Supervisor | W11: 000003 | X11: 000002 | AB11: 000005 | AC11: 000004
A12: 000002 | I12: Traditional Trade | N12: Division Manager | AB12: 000002 | AC12: 000001
A13: 000030 | I13: Traditional Trade | J13: Sales Bangkok | K13: Pathum Thani | N13: Staff | W13: 000003 | X13: 000002 | AB13: 000030 | AC13: 000011
A14: 000031 | I14: Traditional Trade | J14: Sales Bangkok | K14: Nonthaburi | N14: Staff | W14: 000003 | X14: 000002 | AB14: 000031 | AC14: 000008
A15: 000021 | I15: Traditional Trade | J15: Sales Bangkok | K15: Thonburi | N15: Section Manager | W15: 000003 | X15: 000002 | AB15: 000021 | AC15: 000003
A16: 000032 | I16: Traditional Trade | J16: Sales Bangkok | K16: Thonburi | N16: Staff | W16: 000003 | X16: 000002 | AB16: 000032 | AC16: 000021
A17: 000033 | I17: Traditional Trade | J17: Sales Bangkok | K17: Pathum Thani | N17: Staff | W17: 000003 | X17: 000002 | AB17: 000033 | AC17: 000011
A18: 000011 | I18: Traditional Trade | J18: Sales Bangkok | K18: Pathum Thani | N18: Section Manager | W18: 000003 | X18: 000002 | AB18: 000011 | AC18: 000003
A19: 000013 | I19: Traditional Trade | J19: Sales Bangkok | K19: Pathum Thani | N19: Staff | W19: 000003 | X19: 000002 | AB19: 000013 | AC19: 000011
A20: 000034 | I20: Traditional Trade | J20: Sales Bangkok | K20: Thonburi | N20: Staff | W20: 000003 | X20: 000002 | AB20: 000034 | AC20: 000021
A21: 000014 | I21: Traditional Trade | J21: Sales Bangkok | K21: Pathum Thani | N21: Staff | W21: 000003 | X21: 000002 | AB21: 000014 | AC21: 000011
A22: 000017 | I22: Traditional Trade | J22: Sales Bangkok | K22: Pattanakan | N22: Staff | W22: 000003 | X22: 000002 | AB22: 000017 | AC22: 000015
A23: 000009 | I23: Traditional Trade | J23: Sales Bangkok | K23: Nonthaburi | N23: Supervisor | W23: 000003 | X23: 000002 | AB23: 000009 | AC23: 000008
A24: 000035 | I24: Traditional Trade | J24: Sales Bangkok | K24: Thonburi | N24: Staff | W24: 000003 | X24: 000002 | AB24: 000035 | AC24: 000021
... A29: 000039 | I29: Traditional Trade | J29: Sales Bangkok | K29: Pattanakan | N29: Staff | W29: 000003 | X29: 000002 | AB29: 000039 | AC29: 000015
A30: 000003 | I30: Traditional Trade | J30: Sales Bangkok | N30: Department Manager | W30: 000003 | X30: 000002 | AB30: 000003 | AC30: 000002
A31: 000018 | I31: Traditional Trade | J31: Sales Bangkok | K31: Pattanakan | N31: Supervisor | W31: 000003 | X31: 000002 | AB31: 000018 | AC31: 000015
A32: 000023 | I32: Traditional Trade | J32: Sales Bangkok | K32: Thonburi | N32: Supervisor | W32: 000003 | X32: 000002 | AB32: 000023 | AC32: 000021
A33: 000019 | I33: Traditional Trade | J33: Sales Bangkok | K33: Ram Indra | N33: Section Manager | W33: 000003 | X33: 000002 | AB33: 000019 | AC33: 000003
A34: 000040 | I34: Traditional Trade | J34: Sales Bangkok | K34: Pathum Thani | N34: Staff | W34: 000003 | X34: 000002 | AB34: 000040 | AC34: 000011
A35: 000041 | I35: Traditional Trade | J35: Sales Bangkok | K35: Pathum Thani | N35: Staff | W35: 000003 | X35: 000002 | AB35: 000041 | AC35: 000011
A36: 000042 | I36: Traditional Trade | J36: Sales Bangkok | K36: Ram Indra | N36: Staff | W36: 000003 | X36: 000002 | AB36: 000042 | AC36: 000019
A37: 000022 | I37: Traditional Trade | J37: Sales Bangkok | K37: Thonburi | N37: Supervisor | W37: 000003 | X37: 000002 | AB37: 000022 | AC37: 000021
A38: 000016 | I38: Traditional Trade | J38: Sales Bangkok | K38: Pattanakan | N38: Supervisor | W38: 000003 | X38: 000002 | AB38: 000016 | AC38: 000015
A39: 000043 | I39: Traditional Trade | J39: Sales Bangkok | K39: Pathum Thani | N39: Staff | W39: 000003 | X39: 000002 | AB39: 000043 | AC39: 000011
A40: 000044 | I40: Traditional Trade | J40: Sales Bangkok | K40: Nonthaburi | N40: Staff | W40: 000003 | X40: 000002 | AB40: 000044 | AC40: 000008
A41: 000045 | I41: Traditional Trade | J41: Sales Bangkok | K41: Pattanakan | N41: Staff | W41: 000003 | X41: 000002 | AB41: 000045 | AC41: 000015
A42: 000046 | I42: Traditional Trade | J42: Sales Bangkok | K42: Pattanakan | N42: Staff | W42: 000003 | X42: 000002 | AB42: 000046 | AC42: 000015
... A91: 000090 | I91: Traditional Trade | J91: Sales Bangkok | K91: Pathum Thani | N91: Staff | W91: 000003 | X91: 000002 | AB91: 000090 | AC91: 000011

Sheet Actual
A1: Salesman Code | B1: Product | C1: April | D1: May | E1: June | F1: July | G1: August | H1: September | I1: October | J1: November | K1: December | L1: January | M1: February | N1: MaQh
A2: 130003 | B2: A | C2: 12086.3 | D2: 11470.2
A3: 130003 | B3: R | C3: 11168.6 | D3: 11939.8
A4: 130003 | B4: Y | C4: 1598 | D4: 3998
A5: 130003 | B5: M | C5: 2063.5 | D5: 1328.5
A6: 130003 | B6: B | C6: 120 | D6: 1800
A7: 130003 | B7: AP | C7: 1209.6 | D7: 504
A8: 130003 | B8: P | C8: 794.7846
A9: 130003 | B9: NS | C9: 118.8 | D9: 118.8
A10: 130003 | B10: RK | C10: 135 | D10: 27
A11: 130002 | B11: A | C11: 25314.9 | D11: 25517.4
A12: 130002 | B12: R | C12: 7318.8 | D12: 11646.2
A13: 130002 | B13: AP | C13: 4071.84 | D13: 5022.18
A14: 130002 | B14: B | C14: 430 | D14: 2246
A15: 130002 | B15: Y | C15: 576 | D15: 1454
A16: 130002 | B16: P | C16: 804.8394 | D16: 702.6762
A17: 130002 | B17: RK | C17: 162 | D17: 639
A18: 130002 | B18: M | C18: 158.6 | D18: 417.3
A19: 130002 | B19: NS | C19: 246.76 | D19: 60.74
A20: 130002 | B20: T | C20: 200.4 | D20: 4.8
... A26: 130001 | B26: B | C26: 2800 | D26: 4300
A27: 130001 | B27: P | C27: 4299.129
A28: 130001 | B28: M | C28: 1990 | D28: 1436
A29: 130001 | B29: RK | C29: 1794 | D29: 1080
A30: 130001 | B30: T | C30: 1395.6 | D30: 1291.2
A31: 130001 | B31: NS | C31: 502.4 | D31: 747.2
A32: 130001 | B32: Q | C32: 160.992 | D32: 156.672
A33: 150001 | B33: A | C33: 41110.1 | D33: 52562.6
A34: 150001 | B34: R | C34: 20897.4 | D34: 22960.8
A35: 150001 | B35: B | C35: 18064 | D35: 16270
A36: 150001 | B36: AP | C36: 3928.62 | D36: 5880.84
A37: 150001 | B37: Y | C37: 1729 | D37: 4610
A38: 150001 | B38: M | C38: 818.2 | D38: 335.7
A39: 150001 | B39: T | C39: 265.2 | D39: 261.6
... A41: 150001 | B41: RK | C41: 248.4 | D41: 88.2
A42: 150001 | B42: NS | D42: 66.06
A43: 150001 | B43: Q | C43: 5.76 | D43: 28.224
A44: 110003 | B44: A | C44: 8033.6 | D44: 17348.8
A45: 110003 | B45: R | C45: 8907.1 | D45: 11648.4
A46: 110003 | B46: AP | C46: 3326.4 | D46: 2016
...

Sheet Top WS
J1: =$H$4+($H$4*J3) -> 3600 | K1: =$H$4+($H$4*K3) -> 3800
J2: =$H$4+($H$4*J3) -> 3600 | K2: =$H$4+($H$4*K3) -> 3800 | L2: =$H$4+($H$4*L3) -> 4000 | M2: =$H$4+($H$4*M3) -> 4120 | N2: =$H$4+($H$4*N3) -> 4320 | O2: =$H$4+($H$4*O3) -> 4400 | P2: =$H$4+($H$4*P3) -> 4600 | Q2: =$H$4+($H$4*Q3) -> 4800 | R2: =$H$4+($H$4*R3) -> 5200
C3: Job Function | D3: Incentive base | I3: Money | J3: -0.1 | K3: -0.05 | L3: 0 | M3: 0.03 | N3: 0.08 | O3: 0.1 | P3: 0.15 | Q3: 0.2 | R3: 0.3 | U3: Simulation
C4: Depot | D4: Old | E4: New | G4: Incentive $ | H4: 4000 | I4: GOAL | J4: 0.9 | K4: 0.95 | L4: 1 | M4: 1.03 | N4: 1.06 | O4: 1.1 | P4: 1.15 | Q4: 1.2 | R4: 1.3 | W4: 45566 | X4: 45597 | Y4: 45627 | Z4: Total
C5: Area Manger | D5: 5000 | E5: 5000 | U5: Real | V5: Sales (1-2-3-4) | W5: 5000 | X5: 5000 | Y5: 5000 | Z5: =SUM(W5:Y5) -> 15000
C6: Depocho | D6: 4000 | E6: 4000 | G6: G1(CORE) | H6: 0.05 | I6: A | J6: =H6*$J$2 -> 180 | K6: =H6*$K$2 -> 190 | L6: =H6*$L$2 -> 200 | M6: =H6*$M$2 -> 206 | N6: =H6*$N$2 -> 216 | O6: =H6*$O$2 -> 220 | P6: =H6*$P$2 -> 230 | Q6: =H6*$Q$2 -> 240 | R6: =H6*$R$2 -> 260
C7: D.Depocho | D7: 4000 | E7: 4000 | H7: 0.1 | I7: R | J7: =H7*$J$2 -> 360 | K7: =H7*$K$2 -> 380 | L7: =H7*$L$2 -> 400 | M7: =H7*$M$2 -> 412 | N7: =H7*$N$2 -> 432 | O7: =H7*$O$2 -> 440 | P7: =H7*$P$2 -> 460 | Q7: =H7*$Q$2 -> 480 | R7: =H7*$R$2 -> 520 | U7: New Metod | V7: Sales 1 | W7: 6000 | X7: 5000 | Y7: 4500 | Z7: =SUM(W7:Y7) -> 15500
C8: CV | D8: 2500 | E8: 2500 | H8: 0.2 | I8: B | J8: =H8*$J$2 -> 720 | K8: =H8*$K$2 -> 760 | L8: =H8*$L$2 -> 800 | M8: =H8*$M$2 -> 824 | N8: =H8*$N$2 -> 864 | O8: =H8*$O$2 -> 880 | P8: =H8*$P$2 -> 920 | Q8: =H8*$Q$2 -> 960 | R8: =H8*$R$2 -> 1040 | V8: Sales 2 | W8: =I39 -> 1224 | X8: 5200 | Y8: 5000 | Z8: =SUM(W8:Y8) -> 11424
C9: Driver | D9: 1200 | E9: 1200 | V9: Sales3 | W9: 5000 | X9: 4900 | Y9: 6500 | Z9: =SUM(W9:Y9) -> 16400 | AA9: =Z9/Z5 -> 1.0933333
C10: CVFV | E10: 2500 | G10: G2(GD) | H10: 0.05 | I10: AP | J10: =H10*$J$2 -> 180 | K10: =H10*$K$2 -> 190 | L10: =H10*$L$2 -> 200 | M10: =H10*$M$2 -> 206 | N10: =H10*$N$2 -> 216 | O10: =H10*$O$2 -> 220 | P10: =H10*$P$2 -> 230 | Q10: =H10*$Q$2 -> 240 | R10: =H10*$R$2 -> 260 | V10: Sales 4 | W10: 4800 | X10: 4000 | Y10: 5000 | Z10: =SUM(W10:Y10) -> 13800
C11: WSF | E11: 3500 | H11: 0.1 | I11: Q | J11: =H11*$J$2 -> 360 | K11: =H11*$K$2 -> 380 | L11: =H11*$L$2 -> 400 | M11: =H11*$M$2 -> 412 | N11: =H11*$N$2 -> 432 | O11: =H11*$O$2 -> 440 | P11: =H11*$P$2 -> 460 | Q11: =H11*$Q$2 -> 480 | R11: =H11*$R$2 -> 520 | Y11: Average | Z11: =MEDIAN(Z7:Z10) -> 14650 | AA11: =Z11/Z5-1 -> -0.023333333
C12: WH | E12: 3500 | H12: 0.05 | I12: M | J12: =H12*$J$2 -> 180 | K12: =H12*$K$2 -> 190 | L12: =H12*$L$2 -> 200 | M12: =H12*$M$2 -> 206 | N12: =H12*$N$2 -> 216 | O12: =H12*$O$2 -> 220 | P12: =H12*$P$2 -> 230 | Q12: =H12*$Q$2 -> 240 | R12: =H12*$R$2 -> 260
H13: 0.1 | I13: NS | J13: =H13*$J$2 -> 360 | K13: =H13*$K$2 -> 380 | L13: =H13*$L$2 -> 400 | M13: =H13*$M$2 -> 412 | N13: =H13*$N$2 -> 432 | O13: =H13*$O$2 -> 440 | P13: =H13*$P$2 -> 460 | Q13: =H13*$Q$2 -> 480 | R13: =H13*$R$2 -> 520
J14: =H14*$J$2 -> 0 | K14: =H14*$K$2 -> 0 | L14: =H14*$L$2 -> 0 | M14: =H14*$M$2 -> 0 | N14: =H14*$N$2 -> 0 | O14: =H14*$O$2 -> 0 | P14: =H14*$P$2 -> 0 | Q14: =H14*$Q$2 -> 0 | R14: =H14*$R$2 -> 0
G16: G3(BB) | H16: 0.15 | I16: Y | J16: =H16*$J$2 -> 540 | K16: =H16*$K$2 -> 570 | L16: =H16*$L$2 -> 600 | M16: =H16*$M$2 -> 618 | N16: =H16*$N$2 -> 648 | O16: =H16*$O$2 -> 660 | P16: =H16*$P$2 -> 690 | Q16: =H16*$Q$2 -> 720 | R16: =H16*$R$2 -> 780 | U16: Cascade concept
H17: 0.1 | I17: P | J17: =H17*$J$2 -> 360 | K17: =H17*$K$2 -> 380 | L17: =H17*$L$2 -> 400 | M17: =H17*$M$2 -> 412 | N17: =H17*$N$2 -> 432 | O17: =H17*$O$2 -> 440 | P17: =H17*$P$2 -> 460 | Q17: =H17*$Q$2 -> 480 | R17: =H17*$R$2 -> 520
U18: Salesman | V18: Incentive
B19: A | C19: R | D19: B | E19: AP | G19: Others | H19: 0.05 | I19: T | J19: =H19*$J$2 -> 180 | K19: =H19*$K$2 -> 190 | L19: =H19*$L$2 -> 200 | M19: =H19*$M$2 -> 206 | N19: =H19*$N$2 -> 216 | O19: =H19*$O$2 -> 220 | P19: =H19*$P$2 -> 230 | Q19: =H19*$Q$2 -> 240 | R19: =H19*$R$2 -> 260
A20: 0 | B20: =J6 -> 180 | C20: =J7 -> 360 | D20: =J8 -> 720 | E20: =J10 -> 180 | H20: 0.05 | I20: RK | J20: =H20*$J$2 -> 180 | K20: =H20*$K$2 -> 190 | L20: =H20*$L$2 -> 200 | M20: =H20*$M$2 -> 206 | N20: =H20*$N$2 -> 216 | O20: =H20*$O$2 -> 220 | P20: =H20*$P$2 -> 230 | Q20: =H20*$Q$2 -> 240 | R20: =H20*$R$2 -> 260 | U20: All Depot Salesman | V20: Depocho | W20: incentive
A21: 0.90001 | B21: =K6 -> 190 | C21: =K7 -> 380 | D21: =K8 -> 760 | E21: =K10 -> 190
A22: 0.95001 | B22: =L6 -> 200 | C22: =L7 -> 400 | D22: =L8 -> 800 | E22: =L10 -> 200 | U22: All Area depot result | V22: Area Manager | W22: Incentive
A23: 1.00001 | B23: =M6 -> 206 | C23: =M7 -> 412 | D23: =M8 -> 824 | E23: =M10 -> 206
A24: 1.03001 | B24: =N6 -> 216 | C24: =N7 -> 432 | D24: =N8 -> 864 | E24: =N10 -> 216 | U24: All Area manager Result | V24: Division manager | W24: Incetive
A25: =106.001% -> 1.06001 | B25: =O6 -> 220 | C25: =O7 -> 440 | D25: =O8 -> 880 | E25: =O10 -> 220
A26: =110.001% -> 1.10001 | B26: =P6 -> 230 | C26: =P7 -> 460 | D26: =P8 -> 920 | E26: =P10 -> 230
A27: =115.001% -> 1.15001 | B27: =Q6 -> 240 | C27: =Q7 -> 480 | D27: =Q8 -> 960 | E27: =Q10 -> 240
A28: =120.001% -> 1.20001 | B28: =R6 -> 260 | C28: =R7 -> 520 | D28: =R8 -> 1040 | E28: =R10 -> 260
H30: =SUM(H6:H29) -> 1
I31: TOTAL | J31: =SUM(J6:J29) -> 3600 | K31: =SUM(K6:K29) -> 3800 | L31: =SUM(L6:L29) -> 4000 | M31: =SUM(M6:M29) -> 4120 | N31: =SUM(N6:N29) -> 4320 | O31: =SUM(O6:O29) -> 4400 | P31: =SUM(P6:P29) -> 4600 | Q31: =SUM(Q6:Q29) -> 4800 | R31: =SUM(R6:R29) -> 5200
G33: EXTRA | H33: Special KPI
H35: G1 | O35: =O6 -> 220
H36: G2 | J36: =J10 -> 180
H37: G3 | M37: =M16 -> 618
H38: Ot | M38: =M19 -> 206
H39: TOTAL | I39: =SUM(I35:R38) -> 1224
H41: Extreme | I41: <80% | J41: 80% to <90% | K41: 90% to <95% | L41: 95% to <100% | M41: 100% to <105% | N41: 105% to <110% | O41: 110% to <115% | P41: 115% to < 120% | Q41: 120% to <130% | R41: >130%
I42: 0 | J42: 1200 | K42: 1350 | L42: =1425 -> 1425 | M42: 1500 | N42: 1575 | O42: 1725 | P42: 1875 | Q42: 1950 | R42: 2100
H43: Money | J43: -0.2 | K43: -0.1 | L43: -0.05 | N43: 0.05 | O43: 0.15 | P43: 0.25 | Q43: 0.3 | R43: 0.4
H44: Option1 | I44: <80% | J44: 80% to <90% | K44: 90% to <95% | L44: 95% to <100% | M44: 1 | N44: >100% to <=105% | O44: >105% to <=110% | P44: >110% to <=115% | Q44: >115% to < =120% | R44: >120% to > 130%
H45: G1 | I45: =J6 -> 180 | J45: =J6 -> 180 | K45: =K6 -> 190 | L45: =L6 -> 200 | M45: =M6 -> 206 | N45: =N6 -> 216 | O45: =O6 -> 220 | P45: =P6 -> 230 | Q45: =Q6 -> 240 | R45: =R6 -> 260
...

Sheet  WS SF
J1: =$H$4+($H$4*J3) -> 3150 | K1: =$H$4+($H$4*K3) -> 3325
J2: =$H$4+($H$4*J3) -> 3150 | K2: =$H$4+($H$4*K3) -> 3325 | L2: =$H$4+($H$4*L3) -> 3500 | M2: =$H$4+($H$4*M3) -> 3605 | N2: =$H$4+($H$4*N3) -> 3780 | O2: =$H$4+($H$4*O3) -> 3850 | P2: =$H$4+($H$4*P3) -> 4025 | Q2: =$H$4+($H$4*Q3) -> 4200 | R2: =$H$4+($H$4*R3) -> 4550
D3: Incentive base | I3: Money | J3: -0.1 | K3: -0.05 | L3: 0 | M3: 0.03 | N3: 0.08 | O3: 0.1 | P3: 0.15 | Q3: 0.2 | R3: 0.3 | U3: Simulation
C4: Depot | D4: Now | E4: New | G4: Incentive $ | H4: 3500 | I4: GOAL | J4: 0.9 | K4: 0.95 | L4: 1 | M4: 1.03 | N4: 1.06 | O4: 1.1 | P4: 1.15 | Q4: 1.2 | R4: 1.3 | W4: 45566 | X4: 45597 | Y4: 45627 | Z4: Total
C5: Area Manger | D5: 5000 | E5: 5000 | U5: Real | V5: Sales (1-2-3-4) | W5: 5000 | X5: 5000 | Y5: 5000 | Z5: =SUM(W5:Y5) -> 15000
C6: Depocho | D6: 4000 | E6: 4000 | G6: G1(CORE) | H6: 0.05 | I6: A | J6: =H6*$J$2 -> 157.5 | K6: =H6*$K$2 -> 166.25 | L6: =H6*$L$2 -> 175 | M6: =H6*$M$2 -> 180.25 | N6: =H6*$N$2 -> 189 | O6: =H6*$O$2 -> 192.5 | P6: =H6*$P$2 -> 201.25 | Q6: =H6*$Q$2 -> 210 | R6: =H6*$R$2 -> 227.5
C7: D.Depocho | D7: 4000 | E7: 4000 | H7: 0.1 | I7: R | J7: =H7*$J$2 -> 315 | K7: =H7*$K$2 -> 332.5 | L7: =H7*$L$2 -> 350 | M7: =H7*$M$2 -> 360.5 | N7: =H7*$N$2 -> 378 | O7: =H7*$O$2 -> 385 | P7: =H7*$P$2 -> 402.5 | Q7: =H7*$Q$2 -> 420 | R7: =H7*$R$2 -> 455 | U7: New Metod | V7: Sales 1 | W7: 6000 | X7: 5000 | Y7: 4500 | Z7: =SUM(W7:Y7) -> 15500
C8: CV | D8: 2500 | E8: 2500 | H8: 0.1 | I8: B | J8: =H8*$J$2 -> 315 | K8: =H8*$K$2 -> 332.5 | L8: =H8*$L$2 -> 350 | M8: =H8*$M$2 -> 360.5 | N8: =H8*$N$2 -> 378 | O8: =H8*$O$2 -> 385 | P8: =H8*$P$2 -> 402.5 | Q8: =H8*$Q$2 -> 420 | R8: =H8*$R$2 -> 455 | V8: Sales 2 | W8: =I39 -> 1071 | X8: 5200 | Y8: 5000 | Z8: =SUM(W8:Y8) -> 11271
C9: Driver | D9: 1200 | E9: 1200 | V9: Sales3 | W9: 5000 | X9: 4900 | Y9: 6500 | Z9: =SUM(W9:Y9) -> 16400 | AA9: =Z9/Z5 -> 1.0933333
C10: CVFV | E10: 2500 | G10: G2(GD) | H10: 0.05 | I10: AP | J10: =H10*$J$2 -> 157.5 | K10: =H10*$K$2 -> 166.25 | L10: =H10*$L$2 -> 175 | M10: =H10*$M$2 -> 180.25 | N10: =H10*$N$2 -> 189 | O10: =H10*$O$2 -> 192.5 | P10: =H10*$P$2 -> 201.25 | Q10: =H10*$Q$2 -> 210 | R10: =H10*$R$2 -> 227.5 | V10: Sales 4 | W10: 4800 | X10: 4000 | Y10: 5000 | Z10: =SUM(W10:Y10) -> 13800
C11: WSF | E11: 3500 | H11: 0.1 | I11: Q | J11: =H11*$J$2 -> 315 | K11: =H11*$K$2 -> 332.5 | L11: =H11*$L$2 -> 350 | M11: =H11*$M$2 -> 360.5 | N11: =H11*$N$2 -> 378 | O11: =H11*$O$2 -> 385 | P11: =H11*$P$2 -> 402.5 | Q11: =H11*$Q$2 -> 420 | R11: =H11*$R$2 -> 455 | Y11: Average | Z11: =MEDIAN(Z7:Z10) -> 14650 | AA11: =Z11/Z5-1 -> -0.023333333
C12: WH | E12: 3500 | H12: 0.1 | I12: M | J12: =H12*$J$2 -> 315 | K12: =H12*$K$2 -> 332.5 | L12: =H12*$L$2 -> 350 | M12: =H12*$M$2 -> 360.5 | N12: =H12*$N$2 -> 378 | O12: =H12*$O$2 -> 385 | P12: =H12*$P$2 -> 402.5 | Q12: =H12*$Q$2 -> 420 | R12: =H12*$R$2 -> 455
H13: 0.1 | I13: NS | J13: =H13*$J$2 -> 315 | K13: =H13*$K$2 -> 332.5 | L13: =H13*$L$2 -> 350 | M13: =H13*$M$2 -> 360.5 | N13: =H13*$N$2 -> 378 | O13: =H13*$O$2 -> 385 | P13: =H13*$P$2 -> 402.5 | Q13: =H13*$Q$2 -> 420 | R13: =H13*$R$2 -> 455
J14: =H14*$J$2 -> 0 | K14: =H14*$K$2 -> 0 | L14: =H14*$L$2 -> 0 | M14: =H14*$M$2 -> 0 | N14: =H14*$N$2 -> 0 | O14: =H14*$O$2 -> 0 | P14: =H14*$P$2 -> 0 | Q14: =H14*$Q$2 -> 0 | R14: =H14*$R$2 -> 0
G16: G3(BB) | H16: 0.15 | I16: Y | J16: =H16*$J$2 -> 472.5 | K16: =H16*$K$2 -> 498.75 | L16: =H16*$L$2 -> 525 | M16: =H16*$M$2 -> 540.75 | N16: =H16*$N$2 -> 567 | O16: =H16*$O$2 -> 577.5 | P16: =H16*$P$2 -> 603.75 | Q16: =H16*$Q$2 -> 630 | R16: =H16*$R$2 -> 682.5 | U16: Cascade concept
H17: 0.15 | I17: P | J17: =H17*$J$2 -> 472.5 | K17: =H17*$K$2 -> 498.75 | L17: =H17*$L$2 -> 525 | M17: =H17*$M$2 -> 540.75 | N17: =H17*$N$2 -> 567 | O17: =H17*$O$2 -> 577.5 | P17: =H17*$P$2 -> 603.75 | Q17: =H17*$Q$2 -> 630 | R17: =H17*$R$2 -> 682.5
U18: Salesman | V18: Incentive
B19: AP | C19: Q | D19: M | E19: NS | G19: Others | H19: 0.05 | I19: T | J19: =H19*$J$2 -> 157.5 | K19: =H19*$K$2 -> 166.25 | L19: =H19*$L$2 -> 175 | M19: =H19*$M$2 -> 180.25 | N19: =H19*$N$2 -> 189 | O19: =H19*$O$2 -> 192.5 | P19: =H19*$P$2 -> 201.25 | Q19: =H19*$Q$2 -> 210 | R19: =H19*$R$2 -> 227.5
A20: 0 | B20: =J10 -> 157.5 | C20: =J11 -> 315 | D20: =J12 -> 315 | E20: =J13 -> 315 | H20: 0.05 | I20: RK | J20: =H20*$J$2 -> 157.5 | K20: =H20*$K$2 -> 166.25 | L20: =H20*$L$2 -> 175 | M20: =H20*$M$2 -> 180.25 | N20: =H20*$N$2 -> 189 | O20: =H20*$O$2 -> 192.5 | P20: =H20*$P$2 -> 201.25 | Q20: =H20*$Q$2 -> 210 | R20: =H20*$R$2 -> 227.5 | U20: All Depot Salesman | V20: Depocho | W20: incentive
A21: 0.90001 | B21: =K10 -> 166.25 | C21: =K11 -> 332.5 | D21: =K12 -> 332.5 | E21: =K13 -> 332.5
A22: 0.95001 | B22: =L10 -> 175 | C22: =L11 -> 350 | D22: =L12 -> 350 | E22: =L13 -> 350 | U22: All Area depot result | V22: Area Manager | W22: Incentive
A23: 1.00001 | B23: =M10 -> 180.25 | C23: =M11 -> 360.5 | D23: =M12 -> 360.5 | E23: =M13 -> 360.5
A24: 1.03001 | B24: =N10 -> 189 | C24: =N11 -> 378 | D24: =N12 -> 378 | E24: =N13 -> 378 | U24: All Area manager Result | V24: Division manager | W24: Incetive
A25: =106.001% -> 1.06001 | B25: =O10 -> 192.5 | C25: =O11 -> 385 | D25: =O12 -> 385 | E25: =O13 -> 385
A26: =110.001% -> 1.10001 | B26: =P10 -> 201.25 | C26: =P11 -> 402.5 | D26: =P12 -> 402.5 | E26: =P13 -> 402.5
A27: =115.001% -> 1.15001 | B27: =Q10 -> 210 | C27: =Q11 -> 420 | D27: =Q12 -> 420 | E27: =Q13 -> 420
A28: =120.001% -> 1.20001 | B28: =R10 -> 227.5 | C28: =R11 -> 455 | D28: =R12 -> 455 | E28: =R13 -> 455
H30: =SUM(H6:H29) -> 1
I31: TOTAL | J31: =SUM(J6:J29) -> 3150 | K31: =SUM(K6:K29) -> 3325 | L31: =SUM(L6:L29) -> 3500 | M31: =SUM(M6:M29) -> 3605 | N31: =SUM(N6:N29) -> 3780 | O31: =SUM(O6:O29) -> 3850 | P31: =SUM(P6:P29) -> 4025 | Q31: =SUM(Q6:Q29) -> 4200 | R31: =SUM(R6:R29) -> 4550
G33: EXTRA | H33: Special KPI
H35: G1 | O35: =O6 -> 192.5
H36: G2 | J36: =J10 -> 157.5
H37: G3 | M37: =M16 -> 540.75
H38: Ot | M38: =M19 -> 180.25
H39: TOTAL | I39: =SUM(I35:R38) -> 1071
H41: Extreme | I41: <80% | J41: 80% to <90% | K41: 90% to <95% | L41: 95% to <100% | M41: 100% to <105% | N41: 105% to <110% | O41: 110% to <115% | P41: 115% to < 120% | Q41: 120% to <130% | R41: >130%
I42: 0 | J42: 1200 | K42: 1350 | L42: =1425 -> 1425 | M42: 1500 | N42: 1575 | O42: 1725 | P42: 1875 | Q42: 1950 | R42: 2100
H43: Money | J43: -0.2 | K43: -0.1 | L43: -0.05 | N43: 0.05 | O43: 0.15 | P43: 0.25 | Q43: 0.3 | R43: 0.4
H44: Option1 | I44: <80% | J44: 80% to <90% | K44: 90% to <95% | L44: 95% to <100% | M44: 1 | N44: >100% to <=105% | O44: >105% to <=110% | P44: >110% to <=115% | Q44: >115% to < =120% | R44: >120% to > 130%
H45: G1 | I45: =J6 -> 157.5 | J45: =J6 -> 157.5 | K45: =K6 -> 166.25 | L45: =L6 -> 175 | M45: =M6 -> 180.25 | N45: =N6 -> 189 | O45: =O6 -> 192.5 | P45: =P6 -> 201.25 | Q45: =Q6 -> 210 | R45: =R6 -> 227.5
...

Sheet WS WH
J1: =J2 -> 3150 | K1: =$H$4+($H$4*K3) -> 3325
J2: =$H$4+($H$4*J3) -> 3150 | K2: =$H$4+($H$4*K3) -> 3325 | L2: =$H$4+($H$4*L3) -> 3500 | M2: =$H$4+($H$4*M3) -> 3605 | N2: =$H$4+($H$4*N3) -> 3780 | O2: =$H$4+($H$4*O3) -> 3850 | P2: =$H$4+($H$4*P3) -> 4025 | Q2: =$H$4+($H$4*Q3) -> 4200 | R2: =$H$4+($H$4*R3) -> 4550
D3: Incentive base | I3: Money | J3: -0.1 | K3: -0.05 | L3: 0 | M3: 0.03 | N3: 0.08 | O3: 0.1 | P3: 0.15 | Q3: 0.2 | R3: 0.3 | U3: Simulation
C4: Depot | D4: Now | E4: New | G4: Incentive $ | H4: 3500 | I4: GOAL | J4: 0.9 | K4: 0.95 | L4: 1 | M4: 1.03 | N4: 1.06 | O4: 1.1 | P4: 1.15 | Q4: 1.2 | R4: 1.3 | W4: 45566 | X4: 45597 | Y4: 45627 | Z4: Total
C5: Area Manger | D5: 5000 | E5: 5000 | U5: Real | V5: Sales (1-2-3-4) | W5: 5000 | X5: 5000 | Y5: 5000 | Z5: =SUM(W5:Y5) -> 15000
C6: Depocho | D6: 4000 | E6: 4000 | G6: G1(CORE) | H6: 0.1 | I6: A | J6: =H6*$J$2 -> 315 | K6: =H6*$K$2 -> 332.5 | L6: =H6*$L$2 -> 350 | M6: =H6*$M$2 -> 360.5 | N6: =H6*$N$2 -> 378 | O6: =H6*$O$2 -> 385 | P6: =H6*$P$2 -> 402.5 | Q6: =H6*$Q$2 -> 420 | R6: =H6*$R$2 -> 455
C7: D.Depocho | D7: 4000 | E7: 4000 | H7: 0.15 | I7: R | J7: =H7*$J$2 -> 472.5 | K7: =H7*$K$2 -> 498.75 | L7: =H7*$L$2 -> 525 | M7: =H7*$M$2 -> 540.75 | N7: =H7*$N$2 -> 567 | O7: =H7*$O$2 -> 577.5 | P7: =H7*$P$2 -> 603.75 | Q7: =H7*$Q$2 -> 630 | R7: =H7*$R$2 -> 682.5 | U7: New Metod | V7: Sales 1 | W7: 6000 | X7: 5000 | Y7: 4500 | Z7: =SUM(W7:Y7) -> 15500
C8: CV | D8: 2500 | E8: 2500 | H8: 0.25 | I8: B | J8: =H8*$J$2 -> 787.5 | K8: =H8*$K$2 -> 831.25 | L8: =H8*$L$2 -> 875 | M8: =H8*$M$2 -> 901.25 | N8: =H8*$N$2 -> 945 | O8: =H8*$O$2 -> 962.5 | P8: =H8*$P$2 -> 1006.25 | Q8: =H8*$Q$2 -> 1050 | R8: =H8*$R$2 -> 1137.5 | V8: Sales 2 | W8: =I39 -> 1083.25 | X8: 5200 | Y8: 5000 | Z8: =SUM(W8:Y8) -> 11283.25
C9: Driver | D9: 1200 | E9: 1200 | V9: Sales3 | W9: 5000 | X9: 4900 | Y9: 6500 | Z9: =SUM(W9:Y9) -> 16400 | AA9: =Z9/Z5 -> 1.0933333
C10: CVFV | E10: 2500 | G10: G2(GD) | H10: 0.05 | I10: AP | J10: =H10*$J$2 -> 157.5 | K10: =H10*$K$2 -> 166.25 | L10: =H10*$L$2 -> 175 | M10: =H10*$M$2 -> 180.25 | N10: =H10*$N$2 -> 189 | O10: =H10*$O$2 -> 192.5 | P10: =H10*$P$2 -> 201.25 | Q10: =H10*$Q$2 -> 210 | R10: =H10*$R$2 -> 227.5 | V10: Sales 4 | W10: 4800 | X10: 4000 | Y10: 5000 | Z10: =SUM(W10:Y10) -> 13800
C11: WSF | E11: 3500 | H11: 0.05 | I11: Q | J11: =H11*$J$2 -> 157.5 | K11: =H11*$K$2 -> 166.25 | L11: =H11*$L$2 -> 175 | M11: =H11*$M$2 -> 180.25 | N11: =H11*$N$2 -> 189 | O11: =H11*$O$2 -> 192.5 | P11: =H11*$P$2 -> 201.25 | Q11: =H11*$Q$2 -> 210 | R11: =H11*$R$2 -> 227.5 | Y11: Average | Z11: =MEDIAN(Z7:Z10) -> 14650 | AA11: =Z11/Z5-1 -> -0.023333333
C12: WH | E12: 3500 | H12: 0.05 | I12: M | J12: =H12*$J$2 -> 157.5 | K12: =H12*$K$2 -> 166.25 | L12: =H12*$L$2 -> 175 | M12: =H12*$M$2 -> 180.25 | N12: =H12*$N$2 -> 189 | O12: =H12*$O$2 -> 192.5 | P12: =H12*$P$2 -> 201.25 | Q12: =H12*$Q$2 -> 210 | R12: =H12*$R$2 -> 227.5
H13: 0.05 | I13: NS | J13: =H13*$J$2 -> 157.5 | K13: =H13*$K$2 -> 166.25 | L13: =H13*$L$2 -> 175 | M13: =H13*$M$2 -> 180.25 | N13: =H13*$N$2 -> 189 | O13: =H13*$O$2 -> 192.5 | P13: =H13*$P$2 -> 201.25 | Q13: =H13*$Q$2 -> 210 | R13: =H13*$R$2 -> 227.5
J14: =H14*$J$2 -> 0 | K14: =H14*$K$2 -> 0 | L14: =H14*$L$2 -> 0 | M14: =H14*$M$2 -> 0 | N14: =H14*$N$2 -> 0 | O14: =H14*$O$2 -> 0 | P14: =H14*$P$2 -> 0 | Q14: =H14*$Q$2 -> 0 | R14: =H14*$R$2 -> 0
G16: G3(BB) | H16: 0.1 | I16: Y | J16: =H16*$J$2 -> 315 | K16: =H16*$K$2 -> 332.5 | L16: =H16*$L$2 -> 350 | M16: =H16*$M$2 -> 360.5 | N16: =H16*$N$2 -> 378 | O16: =H16*$O$2 -> 385 | P16: =H16*$P$2 -> 402.5 | Q16: =H16*$Q$2 -> 420 | R16: =H16*$R$2 -> 455 | U16: Cascade concept
H17: 0.1 | I17: P | J17: =H17*$J$2 -> 315 | K17: =H17*$K$2 -> 332.5 | L17: =H17*$L$2 -> 350 | M17: =H17*$M$2 -> 360.5 | N17: =H17*$N$2 -> 378 | O17: =H17*$O$2 -> 385 | P17: =H17*$P$2 -> 402.5 | Q17: =H17*$Q$2 -> 420 | R17: =H17*$R$2 -> 455
U18: Salesman | V18: Incentive
B19: AP | C19: Q | D19: M | E19: NS | G19: Others | H19: 0.05 | I19: T | J19: =H19*$J$2 -> 157.5 | K19: =H19*$K$2 -> 166.25 | L19: =H19*$L$2 -> 175 | M19: =H19*$M$2 -> 180.25 | N19: =H19*$N$2 -> 189 | O19: =H19*$O$2 -> 192.5 | P19: =H19*$P$2 -> 201.25 | Q19: =H19*$Q$2 -> 210 | R19: =H19*$R$2 -> 227.5
A20: 0 | B20: =J10 -> 157.5 | C20: =J11 -> 157.5 | D20: =J12 -> 157.5 | E20: =J13 -> 157.5 | H20: 0.05 | I20: RK | J20: =H20*$J$2 -> 157.5 | K20: =H20*$K$2 -> 166.25 | L20: =H20*$L$2 -> 175 | M20: =H20*$M$2 -> 180.25 | N20: =H20*$N$2 -> 189 | O20: =H20*$O$2 -> 192.5 | P20: =H20*$P$2 -> 201.25 | Q20: =H20*$Q$2 -> 210 | R20: =H20*$R$2 -> 227.5 | U20: All Depot Salesman | V20: Depocho | W20: incentive
A21: 0.90001 | B21: =K10 -> 166.25 | C21: =K11 -> 166.25 | D21: =K12 -> 166.25 | E21: =K13 -> 166.25
A22: 0.95001 | B22: =L10 -> 175 | C22: =L11 -> 175 | D22: =L12 -> 175 | E22: =L13 -> 175 | U22: All Area depot result | V22: Area Manager | W22: Incentive
A23: 1.00001 | B23: =M10 -> 180.25 | C23: =M11 -> 180.25 | D23: =M12 -> 180.25 | E23: =M13 -> 180.25
A24: 1.03001 | B24: =N10 -> 189 | C24: =N11 -> 189 | D24: =N12 -> 189 | E24: =N13 -> 189 | U24: All Area manager Result | V24: Division manager | W24: Incetive
A25: =106.001% -> 1.06001 | B25: =O10 -> 192.5 | C25: =O11 -> 192.5 | D25: =O12 -> 192.5 | E25: =O13 -> 192.5
A26: =110.001% -> 1.10001 | B26: =P10 -> 201.25 | C26: =P11 -> 201.25 | D26: =P12 -> 201.25 | E26: =P13 -> 201.25
A27: =115.001% -> 1.15001 | B27: =Q10 -> 210 | C27: =Q11 -> 210 | D27: =Q12 -> 210 | E27: =Q13 -> 210
A28: =120.001% -> 1.20001 | B28: =R10 -> 227.5 | C28: =R11 -> 227.5 | D28: =R12 -> 227.5 | E28: =R13 -> 227.5
H30: =SUM(H6:H29) -> 1
I31: TOTAL | J31: =SUM(J6:J29) -> 3150 | K31: =SUM(K6:K29) -> 3325 | L31: =SUM(L6:L29) -> 3500 | M31: =SUM(M6:M29) -> 3605 | N31: =SUM(N6:N29) -> 3780 | O31: =SUM(O6:O29) -> 3850 | P31: =SUM(P6:P29) -> 4025 | Q31: =SUM(Q6:Q29) -> 4200 | R31: =SUM(R6:R29) -> 4550
G33: EXTRA | H33: Special KPI
H35: G1 | O35: =O6 -> 385
H36: G2 | J36: =J10 -> 157.5
H37: G3 | M37: =M16 -> 360.5
H38: Ot | M38: =M19 -> 180.25
H39: TOTAL | I39: =SUM(I35:R38) -> 1083.25
H41: Extreme | I41: <80% | J41: 80% to <90% | K41: 90% to <95% | L41: 95% to <100% | M41: 100% to <105% | N41: 105% to <110% | O41: 110% to <115% | P41: 115% to < 120% | Q41: 120% to <130% | R41: >130%
I42: 0 | J42: 1200 | K42: 1350 | L42: =1425 -> 1425 | M42: 1500 | N42: 1575 | O42: 1725 | P42: 1875 | Q42: 1950 | R42: 2100
H43: Money | J43: -0.2 | K43: -0.1 | L43: -0.05 | N43: 0.05 | O43: 0.15 | P43: 0.25 | Q43: 0.3 | R43: 0.4
H44: Option1 | I44: <80% | J44: 80% to <90% | K44: 90% to <95% | L44: 95% to <100% | M44: 1 | N44: >100% to <=105% | O44: >105% to <=110% | P44: >110% to <=115% | Q44: >115% to < =120% | R44: >120% to > 130%
H45: G1 | I45: =J6 -> 315 | J45: =J6 -> 315 | K45: =K6 -> 332.5 | L45: =L6 -> 350 | M45: =M6 -> 360.5 | N45: =N6 -> 378 | O45: =O6 -> 385 | P45: =P6 -> 402.5 | Q45: =Q6 -> 420 | R45: =R6 -> 455
...

Sheet Test
A1: Row Labels | E1: 1 | F1: 2 | G1: 3 | H1: 4 | I1: 5 | J1: 6 | K1: 7 | L1: 8 | M1: 9 | N1: 10 | O1: 11 | P1: 12 | Q1: 13 | R1: 14 | S1: 15 | T1: 16 | U1: 17 | V1: 18 | W1: 19
A2: 1190011201 | B2: =VLOOKUP(A2,[1]Sheet2!$A$2:$C$409,2,0) -> 76001 | C2: MR.X | D2: =VLOOKUP(A2,'Actual_Aji Plus'!#REF!,2,0) -> #REF! | E2: 0.9 | F2: 0.9001 | G2: 0.95 | H2: 0.9501 | I2: 1 | J2: 1.0001 | K2: 1.03 | L2: 1.0301 | M2: 1.06 | N2: 1.0601 | O2: 1.1 | P2: 1.1001 | Q2: 1.15 | R2: 1.1501 | S2: 1.2 | T2: 1.2001 | U2: 1.7 | V2: 0.8 | W2: 0.55
E4: 1 | F4: 2 | G4: 3 | H4: 4 | I4: 5 | J4: 6 | K4: 7 | L4: 8 | M4: 9 | N4: 10 | O4: 11 | P4: 12 | Q4: 13 | R4: 14 | S4: 15 | T4: 16 | U4: 17 | V4: 18 | W4: 19
E5: =IFERROR(VLOOKUP(E2,'Top WS'!$A$19:$B$28,2),0) -> 180 | F5: =IFERROR(VLOOKUP(F2,'Top WS'!$A$19:$B$28,2),0) -> 190 | G5: =IFERROR(VLOOKUP(G2,'Top WS'!$A$19:$B$28,2),0) -> 190 | H5: =IFERROR(VLOOKUP(H2,'Top WS'!$A$19:$B$28,2),0) -> 200 | I5: =IFERROR(VLOOKUP(I2,'Top WS'!$A$19:$B$28,2),0) -> 200 | J5: =IFERROR(VLOOKUP(J2,'Top WS'!$A$19:$B$28,2),0) -> 206 | K5: =IFERROR(VLOOKUP(K2,'Top WS'!$A$19:$B$28,2),0) -> 206 | L5: =IFERROR(VLOOKUP(L2,'Top WS'!$A$19:$B$28,2),0) -> 216 | ... W5: =IFERROR(VLOOKUP(W2,'Top WS'!$A$19:$B$28,2),0) -> 180

Sheet SF WH
J1: =$H$4+($H$4*J3) -> 3150 | K1: =$H$4+($H$4*K3) -> 3325
J2: =$H$4+($H$4*J3) -> 3150 | K2: =$H$4+($H$4*K3) -> 3325 | L2: =$H$4+($H$4*L3) -> 3500 | M2: =$H$4+($H$4*M3) -> 3605 | N2: =$H$4+($H$4*N3) -> 3780 | O2: =$H$4+($H$4*O3) -> 3850 | P2: =$H$4+($H$4*P3) -> 4025 | Q2: =$H$4+($H$4*Q3) -> 4200 | R2: =$H$4+($H$4*R3) -> 4550
D3: Incentive base | I3: Money | J3: -0.1 | K3: -0.05 | L3: 0 | M3: 0.03 | N3: 0.08 | O3: 0.1 | P3: 0.15 | Q3: 0.2 | R3: 0.3 | U3: Simulation
C4: Depot | D4: Now | E4: New | G4: Incentive $ | H4: 3500 | I4: GOAL | J4: 0.9 | K4: 0.95 | L4: 1 | M4: 1.03 | N4: 1.06 | O4: 1.1 | P4: 1.15 | Q4: 1.2 | R4: 1.3 | W4: 45566 | X4: 45597 | Y4: 45627 | Z4: Total
C5: Area Manger | D5: 5000 | E5: 5000 | U5: Real | V5: Sales (1-2-3-4) | W5: 5000 | X5: 5000 | Y5: 5000 | Z5: =SUM(W5:Y5) -> 15000
C6: Depocho | D6: 4000 | E6: 4000 | G6: G1(CORE) | H6: 0.08 | I6: A | J6: =H6*$J$2 -> 252 | K6: =H6*$K$2 -> 266 | L6: =H6*$L$2 -> 280 | M6: =H6*$M$2 -> 288.4 | N6: =H6*$N$2 -> 302.4 | O6: =H6*$O$2 -> 308 | P6: =H6*$P$2 -> 322 | Q6: =H6*$Q$2 -> 336 | R6: =H6*$R$2 -> 364
C7: D.Depocho | D7: 4000 | E7: 4000 | H7: 0.13 | I7: R | J7: =H7*$J$2 -> 409.5 | K7: =H7*$K$2 -> 432.25 | L7: =H7*$L$2 -> 455 | M7: =H7*$M$2 -> 468.65 | N7: =H7*$N$2 -> 491.4 | O7: =H7*$O$2 -> 500.5 | P7: =H7*$P$2 -> 523.25 | Q7: =H7*$Q$2 -> 546 | R7: =H7*$R$2 -> 591.5 | U7: New Metod | V7: Sales 1 | W7: 6000 | X7: 5000 | Y7: 4500 | Z7: =SUM(W7:Y7) -> 15500
C8: CV | D8: 2500 | E8: 2500 | H8: 0.18 | I8: B | J8: =H8*$J$2 -> 567 | K8: =H8*$K$2 -> 598.5 | L8: =H8*$L$2 -> 630 | M8: =H8*$M$2 -> 648.9 | N8: =H8*$N$2 -> 680.4 | O8: =H8*$O$2 -> 693 | P8: =H8*$P$2 -> 724.5 | Q8: =H8*$Q$2 -> 756 | R8: =H8*$R$2 -> 819 | V8: Sales 2 | W8: =I39 -> 1114.4 | X8: 5200 | Y8: 5000 | Z8: =SUM(W8:Y8) -> 11314.4
C9: Driver | D9: 1200 | E9: 1200 | V9: Sales3 | W9: 5000 | X9: 4900 | Y9: 6500 | Z9: =SUM(W9:Y9) -> 16400 | AA9: =Z9/Z5 -> 1.0933333
C10: CVFV | E10: 2500 | G10: G2(GD) | H10: 0.05 | I10: AP | J10: =H10*$J$2 -> 157.5 | K10: =H10*$K$2 -> 166.25 | L10: =H10*$L$2 -> 175 | M10: =H10*$M$2 -> 180.25 | N10: =H10*$N$2 -> 189 | O10: =H10*$O$2 -> 192.5 | P10: =H10*$P$2 -> 201.25 | Q10: =H10*$Q$2 -> 210 | R10: =H10*$R$2 -> 227.5 | V10: Sales 4 | W10: 4800 | X10: 4000 | Y10: 5000 | Z10: =SUM(W10:Y10) -> 13800
C11: WSF | E11: 3500 | H11: 0.06 | I11: Q | J11: =H11*$J$2 -> 189 | K11: =H11*$K$2 -> 199.5 | L11: =H11*$L$2 -> 210 | M11: =H11*$M$2 -> 216.3 | N11: =H11*$N$2 -> 226.8 | O11: =H11*$O$2 -> 231 | P11: =H11*$P$2 -> 241.5 | Q11: =H11*$Q$2 -> 252 | R11: =H11*$R$2 -> 273 | Y11: Average | Z11: =MEDIAN(Z7:Z10) -> 14650 | AA11: =Z11/Z5-1 -> -0.023333333
C12: WH | E12: 3500 | H12: 0.07 | I12: M | J12: =H12*$J$2 -> 220.5 | K12: =H12*$K$2 -> 232.75 | L12: =H12*$L$2 -> 245 | M12: =H12*$M$2 -> 252.35 | N12: =H12*$N$2 -> 264.6 | O12: =H12*$O$2 -> 269.5 | P12: =H12*$P$2 -> 281.75 | Q12: =H12*$Q$2 -> 294 | R12: =H12*$R$2 -> 318.5
H13: 0.07 | I13: NS | J13: =H13*$J$2 -> 220.5 | K13: =H13*$K$2 -> 232.75 | L13: =H13*$L$2 -> 245 | M13: =H13*$M$2 -> 252.35 | N13: =H13*$N$2 -> 264.6 | O13: =H13*$O$2 -> 269.5 | P13: =H13*$P$2 -> 281.75 | Q13: =H13*$Q$2 -> 294 | R13: =H13*$R$2 -> 318.5
J14: =H14*$J$2 -> 0 | K14: =H14*$K$2 -> 0 | L14: =H14*$L$2 -> 0 | M14: =H14*$M$2 -> 0 | N14: =H14*$N$2 -> 0 | O14: =H14*$O$2 -> 0 | P14: =H14*$P$2 -> 0 | Q14: =H14*$Q$2 -> 0 | R14: =H14*$R$2 -> 0
G16: G3(BB) | H16: 0.13 | I16: Y | J16: =H16*$J$2 -> 409.5 | K16: =H16*$K$2 -> 432.25 | L16: =H16*$L$2 -> 455 | M16: =H16*$M$2 -> 468.65 | N16: =H16*$N$2 -> 491.4 | O16: =H16*$O$2 -> 500.5 | P16: =H16*$P$2 -> 523.25 | Q16: =H16*$Q$2 -> 546 | R16: =H16*$R$2 -> 591.5 | U16: Cascade concept
H17: 0.13 | I17: P | J17: =H17*$J$2 -> 409.5 | K17: =H17*$K$2 -> 432.25 | L17: =H17*$L$2 -> 455 | M17: =H17*$M$2 -> 468.65 | N17: =H17*$N$2 -> 491.4 | O17: =H17*$O$2 -> 500.5 | P17: =H17*$P$2 -> 523.25 | Q17: =H17*$Q$2 -> 546 | R17: =H17*$R$2 -> 591.5
U18: Salesman | V18: Incentive
B19: AP | C19: Q | D19: M | E19: NS | G19: Others | H19: 0.05 | I19: T | J19: =H19*$J$2 -> 157.5 | K19: =H19*$K$2 -> 166.25 | L19: =H19*$L$2 -> 175 | M19: =H19*$M$2 -> 180.25 | N19: =H19*$N$2 -> 189 | O19: =H19*$O$2 -> 192.5 | P19: =H19*$P$2 -> 201.25 | Q19: =H19*$Q$2 -> 210 | R19: =H19*$R$2 -> 227.5
A20: 0 | B20: =J10 -> 157.5 | C20: =J11 -> 189 | D20: =J12 -> 220.5 | E20: =J13 -> 220.5 | H20: 0.05 | I20: RK | J20: =H20*$J$2 -> 157.5 | K20: =H20*$K$2 -> 166.25 | L20: =H20*$L$2 -> 175 | M20: =H20*$M$2 -> 180.25 | N20: =H20*$N$2 -> 189 | O20: =H20*$O$2 -> 192.5 | P20: =H20*$P$2 -> 201.25 | Q20: =H20*$Q$2 -> 210 | R20: =H20*$R$2 -> 227.5 | U20: All Depot Salesman | V20: Depocho | W20: incentive
A21: 0.90001 | B21: =K10 -> 166.25 | C21: =K11 -> 199.5 | D21: =K12 -> 232.75 | E21: =K13 -> 232.75
A22: 0.95001 | B22: =L10 -> 175 | C22: =L11 -> 210 | D22: =L12 -> 245 | E22: =L13 -> 245 | U22: All Area depot result | V22: Area Manager | W22: Incentive
A23: 1.00001 | B23: =M10 -> 180.25 | C23: =M11 -> 216.3 | D23: =M12 -> 252.35 | E23: =M13 -> 252.35
A24: 1.03001 | B24: =N10 -> 189 | C24: =N11 -> 226.8 | D24: =N12 -> 264.6 | E24: =N13 -> 264.6 | U24: All Area manager Result | V24: Division manager | W24: Incetive
A25: =106.001% -> 1.06001 | B25: =O10 -> 192.5 | C25: =O11 -> 231 | D25: =O12 -> 269.5 | E25: =O13 -> 269.5
A26: =110.001% -> 1.10001 | B26: =P10 -> 201.25 | C26: =P11 -> 241.5 | D26: =P12 -> 281.75 | E26: =P13 -> 281.75
A27: =115.001% -> 1.15001 | B27: =Q10 -> 210 | C27: =Q11 -> 252 | D27: =Q12 -> 294 | E27: =Q13 -> 294
A28: =120.001% -> 1.20001 | B28: =R10 -> 227.5 | C28: =R11 -> 273 | D28: =R12 -> 318.5 | E28: =R13 -> 318.5
H30: =SUM(H6:H29) -> 1
I31: TOTAL | J31: =SUM(J6:J29) -> 3150 | K31: =SUM(K6:K29) -> 3325 | L31: =SUM(L6:L29) -> 3500 | M31: =SUM(M6:M29) -> 3605 | N31: =SUM(N6:N29) -> 3780 | O31: =SUM(O6:O29) -> 3850 | P31: =SUM(P6:P29) -> 4025 | Q31: =SUM(Q6:Q29) -> 4200 | R31: =SUM(R6:R29) -> 4550
G33: EXTRA | H33: Special KPI
H35: G1 | O35: =O6 -> 308
H36: G2 | J36: =J10 -> 157.5
H37: G3 | M37: =M16 -> 468.65
H38: Ot | M38: =M19 -> 180.25
H39: TOTAL | I39: =SUM(I35:R38) -> 1114.4
H41: Extreme | I41: <80% | J41: 80% to <90% | K41: 90% to <95% | L41: 95% to <100% | M41: 100% to <105% | N41: 105% to <110% | O41: 110% to <115% | P41: 115% to < 120% | Q41: 120% to <130% | R41: >130%
I42: 0 | J42: 1200 | K42: 1350 | L42: =1425 -> 1425 | M42: 1500 | N42: 1575 | O42: 1725 | P42: 1875 | Q42: 1950 | R42: 2100
H43: Money | J43: -0.2 | K43: -0.1 | L43: -0.05 | N43: 0.05 | O43: 0.15 | P43: 0.25 | Q43: 0.3 | R43: 0.4
H44: Option1 | I44: <80% | J44: 80% to <90% | K44: 90% to <95% | L44: 95% to <100% | M44: 1 | N44: >100% to <=105% | O44: >105% to <=110% | P44: >110% to <=115% | Q44: >115% to < =120% | R44: >120% to > 130%
H45: G1 | I45: =J6 -> 252 | J45: =J6 -> 252 | K45: =K6 -> 266 | L45: =L6 -> 280 | M45: =M6 -> 288.4 | N45: =N6 -> 302.4 | O45: =O6 -> 308 | P45: =P6 -> 322 | Q45: =Q6 -> 336 | R45: =R6 -> 364
...

Sheet Product
A1: Product
A2: AJINOMOTO
A3: ROSDEE
A4: BIRDY
A5: YUMYUM
A6: POWDER COFFEE
A7: AJI-PLUS
A8: ROSDEE MENU
A9: Takumi-Aji
A10: ROSDEE CUBE
A11: ROSDEE MENU KKR
A12: ROSDEE NOODLE

Sheet 2) หลักการคำนวน Table
E1: 0 | F1: =E4+0.0001 -> 0.9001 | G1: =F4+0.0001 -> 0.9501 | H1: =G4+0.0001 -> 1.0001 | I1: =H4+0.0001 -> 1.0301 | J1: =I4+0.0001 -> 1.0601 | K1: =J4+0.0001 -> 1.1001 | L1: =K4+0.0001 -> 1.1501 | M1: =L4+0.0001 -> 1.2001 | N1: =M4+0.0001 -> 1.3001
A2: Top WS | C2: =C4=SUM(G6:G20) -> TRUE | E2: ='Top WS'!J2 -> 3600 | F2: ='Top WS'!K2 -> 3800 | G2: ='Top WS'!L2 -> 4000 | H2: ='Top WS'!M2 -> 4120 | I2: ='Top WS'!N2 -> 4320 | J2: ='Top WS'!O2 -> 4400 | K2: ='Top WS'!P2 -> 4600 | L2: ='Top WS'!Q2 -> 4800 | M2: ='Top WS'!R2 -> 5200
D3: Money | E3: -0.1 | F3: -0.05 | G3: 0 | H3: 0.03 | I3: 0.08 | J3: 0.1 | K3: 0.15 | L3: 0.2 | M3: 0.3
B4: Incentive $ | C4: ='Top WS'!H4 -> 4000 | D4: GOAL | E4: 0.9 | F4: 0.95 | G4: 1 | H4: 1.03 | I4: 1.06 | J4: 1.1 | K4: 1.15 | L4: 1.2 | M4: 1.3
E5: 2 | F5: 3 | G5: 4 | H5: 5 | I5: 6 | J5: 7 | K5: 8 | L5: 9 | M5: 10
B6: G1(CORE) | C6: ='Top WS'!H6 -> 0.05 | D6: ='Top WS'!I6 -> A | E6: ='Top WS'!J6 -> 180 | F6: ='Top WS'!K6 -> 190 | G6: ='Top WS'!L6 -> 200 | H6: ='Top WS'!M6 -> 206 | I6: ='Top WS'!N6 -> 216 | J6: ='Top WS'!O6 -> 220 | ... M6: ='Top WS'!R6 -> 260
C7: ='Top WS'!H7 -> 0.1 | D7: ='Top WS'!I7 -> R | E7: ='Top WS'!J7 -> 360 | F7: ='Top WS'!K7 -> 380 | G7: ='Top WS'!L7 -> 400 | H7: ='Top WS'!M7 -> 412 | I7: ='Top WS'!N7 -> 432 | J7: ='Top WS'!O7 -> 440 | ... M7: ='Top WS'!R7 -> 520
C8: ='Top WS'!H8 -> 0.2 | D8: ='Top WS'!I8 -> B | E8: ='Top WS'!J8 -> 720 | F8: ='Top WS'!K8 -> 760 | G8: ='Top WS'!L8 -> 800 | H8: ='Top WS'!M8 -> 824 | I8: ='Top WS'!N8 -> 864 | J8: ='Top WS'!O8 -> 880 | ... M8: ='Top WS'!R8 -> 1040
B10: G2(GD) | C10: ='Top WS'!H10 -> 0.05 | D10: ='Top WS'!I10 -> AP | E10: ='Top WS'!J10 -> 180 | F10: ='Top WS'!K10 -> 190 | G10: ='Top WS'!L10 -> 200 | H10: ='Top WS'!M10 -> 206 | I10: ='Top WS'!N10 -> 216 | J10: ='Top WS'!O10 -> 220 | ... M10: ='Top WS'!R10 -> 260
C11: ='Top WS'!H11 -> 0.1 | D11: ='Top WS'!I11 -> Q | E11: ='Top WS'!J11 -> 360 | F11: ='Top WS'!K11 -> 380 | G11: ='Top WS'!L11 -> 400 | H11: ='Top WS'!M11 -> 412 | I11: ='Top WS'!N11 -> 432 | J11: ='Top WS'!O11 -> 440 | ... M11: ='Top WS'!R11 -> 520
C12: ='Top WS'!H12 -> 0.05 | D12: ='Top WS'!I12 -> M | E12: ='Top WS'!J12 -> 180 | F12: ='Top WS'!K12 -> 190 | G12: ='Top WS'!L12 -> 200 | H12: ='Top WS'!M12 -> 206 | I12: ='Top WS'!N12 -> 216 | J12: ='Top WS'!O12 -> 220 | ... M12: ='Top WS'!R12 -> 260
C13: ='Top WS'!H13 -> 0.1 | D13: ='Top WS'!I13 -> NS | E13: ='Top WS'!J13 -> 360 | F13: ='Top WS'!K13 -> 380 | G13: ='Top WS'!L13 -> 400 | H13: ='Top WS'!M13 -> 412 | I13: ='Top WS'!N13 -> 432 | J13: ='Top WS'!O13 -> 440 | ... M13: ='Top WS'!R13 -> 520
B16: G3(BB) | C16: ='Top WS'!H16 -> 0.15 | D16: ='Top WS'!I16 -> Y | E16: ='Top WS'!J16 -> 540 | F16: ='Top WS'!K16 -> 570 | G16: ='Top WS'!L16 -> 600 | H16: ='Top WS'!M16 -> 618 | I16: ='Top WS'!N16 -> 648 | J16: ='Top WS'!O16 -> 660 | ... M16: ='Top WS'!R16 -> 780
C17: ='Top WS'!H17 -> 0.1 | D17: ='Top WS'!I17 -> P | E17: ='Top WS'!J17 -> 360 | F17: ='Top WS'!K17 -> 380 | G17: ='Top WS'!L17 -> 400 | H17: ='Top WS'!M17 -> 412 | I17: ='Top WS'!N17 -> 432 | J17: ='Top WS'!O17 -> 440 | ... M17: ='Top WS'!R17 -> 520
B19: Others | C19: ='Top WS'!H19 -> 0.05 | D19: ='Top WS'!I19 -> T | E19: ='Top WS'!J19 -> 180 | F19: ='Top WS'!K19 -> 190 | G19: ='Top WS'!L19 -> 200 | H19: ='Top WS'!M19 -> 206 | I19: ='Top WS'!N19 -> 216 | J19: ='Top WS'!O19 -> 220 | ... M19: ='Top WS'!R19 -> 260
C20: ='Top WS'!H20 -> 0.05 | D20: ='Top WS'!I20 -> RK | E20: ='Top WS'!J20 -> 180 | F20: ='Top WS'!K20 -> 190 | G20: ='Top WS'!L20 -> 200 | H20: ='Top WS'!M20 -> 206 | I20: ='Top WS'!N20 -> 216 | J20: ='Top WS'!O20 -> 220 | ... M20: ='Top WS'!R20 -> 260
A30: WS SF | C30: =C32=SUM(G34:G48) -> TRUE | E30: =' WS SF'!J2 -> 3150 | F30: =' WS SF'!K2 -> 3325 | G30: =' WS SF'!L2 -> 3500 | H30: =' WS SF'!M2 -> 3605 | I30: =' WS SF'!N2 -> 3780 | J30: =' WS SF'!O2 -> 3850 | K30: =' WS SF'!P2 -> 4025 | L30: =' WS SF'!Q2 -> 4200 | M30: =' WS SF'!R2 -> 4550
D31: Money | E31: =' WS SF'!J3 -> -0.1 | F31: =' WS SF'!K3 -> -0.05 | G31: =' WS SF'!L3 -> 0 | H31: =' WS SF'!M3 -> 0.03 | I31: =' WS SF'!N3 -> 0.08 | J31: =' WS SF'!O3 -> 0.1 | K31: =' WS SF'!P3 -> 0.15 | L31: =' WS SF'!Q3 -> 0.2 | M31: =' WS SF'!R3 -> 0.3
B32: Incentive $ | C32: =' WS SF'!H4 -> 3500 | D32: GOAL | E32: =' WS SF'!J4 -> 0.9 | F32: =' WS SF'!K4 -> 0.95 | G32: =' WS SF'!L4 -> 1 | H32: =' WS SF'!M4 -> 1.03 | I32: =' WS SF'!N4 -> 1.06 | J32: =' WS SF'!O4 -> 1.1 | K32: =' WS SF'!P4 -> 1.15 | L32: =' WS SF'!Q4 -> 1.2 | M32: =' WS SF'!R4 -> 1.3
E33: 2 | F33: 3 | G33: 4 | H33: 5 | I33: 6 | J33: 7 | K33: 8 | L33: 9 | M33: 10
B34: G1(CORE) | C34: =' WS SF'!H6 -> 0.05 | D34: =' WS SF'!I6 -> A | E34: =' WS SF'!J6 -> 157.5 | F34: =' WS SF'!K6 -> 166.25 | G34: =' WS SF'!L6 -> 175 | H34: =' WS SF'!M6 -> 180.25 | I34: =' WS SF'!N6 -> 189 | J34: =' WS SF'!O6 -> 192.5 | ... M34: =' WS SF'!R6 -> 227.5
C35: =' WS SF'!H7 -> 0.1 | D35: =' WS SF'!I7 -> R | E35: =' WS SF'!J7 -> 315 | F35: =' WS SF'!K7 -> 332.5 | G35: =' WS SF'!L7 -> 350 | H35: =' WS SF'!M7 -> 360.5 | I35: =' WS SF'!N7 -> 378 | J35: =' WS SF'!O7 -> 385 | ... M35: =' WS SF'!R7 -> 455
C36: =' WS SF'!H8 -> 0.1 | D36: =' WS SF'!I8 -> B | E36: =' WS SF'!J8 -> 315 | F36: =' WS SF'!K8 -> 332.5 | G36: =' WS SF'!L8 -> 350 | H36: =' WS SF'!M8 -> 360.5 | I36: =' WS SF'!N8 -> 378 | J36: =' WS SF'!O8 -> 385 | ... M36: =' WS SF'!R8 -> 455
B38: G2(GD) | C38: =' WS SF'!H10 -> 0.05 | D38: =' WS SF'!I10 -> AP | E38: =' WS SF'!J10 -> 157.5 | F38: =' WS SF'!K10 -> 166.25 | G38: =' WS SF'!L10 -> 175 | H38: =' WS SF'!M10 -> 180.25 | I38: =' WS SF'!N10 -> 189 | J38: =' WS SF'!O10 -> 192.5 | ... M38: =' WS SF'!R10 -> 227.5
C39: =' WS SF'!H11 -> 0.1 | D39: =' WS SF'!I11 -> Q | E39: =' WS SF'!J11 -> 315 | F39: =' WS SF'!K11 -> 332.5 | G39: =' WS SF'!L11 -> 350 | H39: =' WS SF'!M11 -> 360.5 | I39: =' WS SF'!N11 -> 378 | J39: =' WS SF'!O11 -> 385 | ... M39: =' WS SF'!R11 -> 455
C40: =' WS SF'!H12 -> 0.1 | D40: =' WS SF'!I12 -> M | E40: =' WS SF'!J12 -> 315 | F40: =' WS SF'!K12 -> 332.5 | G40: =' WS SF'!L12 -> 350 | H40: =' WS SF'!M12 -> 360.5 | I40: =' WS SF'!N12 -> 378 | J40: =' WS SF'!O12 -> 385 | ... M40: =' WS SF'!R12 -> 455
C41: =' WS SF'!H13 -> 0.1 | D41: =' WS SF'!I13 -> NS | E41: =' WS SF'!J13 -> 315 | F41: =' WS SF'!K13 -> 332.5 | G41: =' WS SF'!L13 -> 350 | H41: =' WS SF'!M13 -> 360.5 | I41: =' WS SF'!N13 -> 378 | J41: =' WS SF'!O13 -> 385 | ... M41: =' WS SF'!R13 -> 455
C42: =' WS SF'!H14 -> 0 | D42: =' WS SF'!I14 -> 0 | E42: =' WS SF'!J14 -> 0 | F42: =' WS SF'!K14 -> 0 | G42: =' WS SF'!L14 -> 0 | H42: =' WS SF'!M14 -> 0 | I42: =' WS SF'!N14 -> 0 | J42: =' WS SF'!O14 -> 0 | ... M42: =' WS SF'!R14 -> 0
B44: G3(BB) | C44: =' WS SF'!H16 -> 0.15 | D44: =' WS SF'!I16 -> Y | E44: =' WS SF'!J16 -> 472.5 | F44: =' WS SF'!K16 -> 498.75 | G44: =' WS SF'!L16 -> 525 | H44: =' WS SF'!M16 -> 540.75 | I44: =' WS SF'!N16 -> 567 | J44: =' WS SF'!O16 -> 577.5 | ... M44: =' WS SF'!R16 -> 682.5
C45: =' WS SF'!H17 -> 0.15 | D45: =' WS SF'!I17 -> P | E45: =' WS SF'!J17 -> 472.5 | F45: =' WS SF'!K17 -> 498.75 | G45: =' WS SF'!L17 -> 525 | H45: =' WS SF'!M17 -> 540.75 | I45: =' WS SF'!N17 -> 567 | J45: =' WS SF'!O17 -> 577.5 | ... M45: =' WS SF'!R17 -> 682.5
B47: Others | C47: =' WS SF'!H19 -> 0.05 | D47: =' WS SF'!I19 -> T | E47: =' WS SF'!J19 -> 157.5 | F47: =' WS SF'!K19 -> 166.25 | G47: =' WS SF'!L19 -> 175 | H47: =' WS SF'!M19 -> 180.25 | I47: =' WS SF'!N19 -> 189 | J47: =' WS SF'!O19 -> 192.5 | ... M47: =' WS SF'!R19 -> 227.5
C48: =' WS SF'!H20 -> 0.05 | D48: =' WS SF'!I20 -> RK | E48: =' WS SF'!J20 -> 157.5 | F48: =' WS SF'!K20 -> 166.25 | G48: =' WS SF'!L20 -> 175 | H48: =' WS SF'!M20 -> 180.25 | I48: =' WS SF'!N20 -> 189 | J48: =' WS SF'!O20 -> 192.5 | ... M48: =' WS SF'!R20 -> 227.5
A60: WS WH | C60: =C62=SUM(G64:G78) -> TRUE | E60: ='WS WH'!J2 -> 3150 | F60: ='WS WH'!K2 -> 3325 | G60: ='WS WH'!L2 -> 3500 | H60: ='WS WH'!M2 -> 3605 | I60: ='WS WH'!N2 -> 3780 | J60: ='WS WH'!O2 -> 3850 | K60: ='WS WH'!P2 -> 4025 | L60: ='WS WH'!Q2 -> 4200 | M60: ='WS WH'!R2 -> 4550
D61: Money | E61: ='WS WH'!J3 -> -0.1 | F61: ='WS WH'!K3 -> -0.05 | G61: ='WS WH'!L3 -> 0 | H61: ='WS WH'!M3 -> 0.03 | I61: ='WS WH'!N3 -> 0.08 | J61: ='WS WH'!O3 -> 0.1 | K61: ='WS WH'!P3 -> 0.15 | L61: ='WS WH'!Q3 -> 0.2 | M61: ='WS WH'!R3 -> 0.3
B62: Incentive $ | C62: 3500 | D62: GOAL | E62: ='WS WH'!J4 -> 0.9 | F62: ='WS WH'!K4 -> 0.95 | G62: ='WS WH'!L4 -> 1 | H62: ='WS WH'!M4 -> 1.03 | I62: ='WS WH'!N4 -> 1.06 | J62: ='WS WH'!O4 -> 1.1 | K62: ='WS WH'!P4 -> 1.15 | L62: ='WS WH'!Q4 -> 1.2 | M62: ='WS WH'!R4 -> 1.3
E63: 2 | F63: 3 | G63: 4 | H63: 5 | I63: 6 | J63: 7 | K63: 8 | L63: 9 | M63: 10
B64: G1(CORE) | C64: ='WS WH'!H6 -> 0.1 | D64: ='WS WH'!I6 -> A | E64: ='WS WH'!J6 -> 315 | F64: ='WS WH'!K6 -> 332.5 | G64: ='WS WH'!L6 -> 350 | H64: ='WS WH'!M6 -> 360.5 | I64: ='WS WH'!N6 -> 378 | J64: ='WS WH'!O6 -> 385 | ... M64: ='WS WH'!R6 -> 455
C65: ='WS WH'!H7 -> 0.15 | D65: ='WS WH'!I7 -> R | E65: ='WS WH'!J7 -> 472.5 | F65: ='WS WH'!K7 -> 498.75 | G65: ='WS WH'!L7 -> 525 | H65: ='WS WH'!M7 -> 540.75 | I65: ='WS WH'!N7 -> 567 | J65: ='WS WH'!O7 -> 577.5 | ... M65: ='WS WH'!R7 -> 682.5
C66: ='WS WH'!H8 -> 0.25 | D66: ='WS WH'!I8 -> B | E66: ='WS WH'!J8 -> 787.5 | F66: ='WS WH'!K8 -> 831.25 | G66: ='WS WH'!L8 -> 875 | H66: ='WS WH'!M8 -> 901.25 | I66: ='WS WH'!N8 -> 945 | J66: ='WS WH'!O8 -> 962.5 | ... M66: ='WS WH'!R8 -> 1137.5
B68: G2(GD) | C68: ='WS WH'!H10 -> 0.05 | D68: ='WS WH'!I10 -> AP | E68: ='WS WH'!J10 -> 157.5 | F68: ='WS WH'!K10 -> 166.25 | G68: ='WS WH'!L10 -> 175 | H68: ='WS WH'!M10 -> 180.25 | I68: ='WS WH'!N10 -> 189 | J68: ='WS WH'!O10 -> 192.5 | ... M68: ='WS WH'!R10 -> 227.5
...

Sheet 3)Target & Cal
B1: ชื่อต้องตรงกับ BI | D1: Target | P1: Actual | AB1: PeQent (Actual vs Target) | AN1: PeQent (Round) (Actual vs Target) | AZ1: Incentive | BM1: Direct Sup.
D2: 2 | E2: 3 | F2: 4 | G2: 5 | H2: 6 | I2: 7 | J2: 8 | K2: 9 | L2: 10 | M2: 11 | N2: 12 | O2: 13 | P2: 2 | Q2: 3 | R2: 4 | S2: 5 | T2: 6 | U2: 7 | V2: 8 | W2: 9 | X2: 10 | Y2: 11 | Z2: 12 | AA2: 13 | AB2: 2 | AC2: 3 | AD2: 4 | AE2: 5 | AF2: 6 | AG2: 7 | AH2: 8 | AI2: 9 | AJ2: 10 | AK2: 11 | AL2: 12 | AM2: 13 | AN2: 2 | AO2: 3 | AP2: 4 | AQ2: 5 | AR2: 6 | AS2: 7 | AT2: 8 | AU2: 9 | AV2: 10 | AW2: 11 | AX2: 12 | AY2: 13 | AZ2: 2 | BA2: 3 | BB2: 4 | BC2: 5 | BD2: 6 | BE2: 7 | BF2: 8 | BG2: 9 | BH2: 10 | BI2: 11 | BJ2: 12 | BK2: 13
A3: SalesmanCode | B3: Product | C3: Team | D3: Apr_T | E3: May_T | F3: Jun_T | G3: Jul_T | H3: Aug_T | I3: Sep_T | J3: Oct_T | K3: Nov_T | L3: Dec_T | M3: Jan_T | N3: Feb_T | O3: Mar_T | P3: Apr_A | Q3: May_A | R3: Jun_A | S3: Jul_A | T3: Aug_A | U3: Sep_A | V3: Oct_A | W3: Nov_A | X3: Dec_A | Y3: Jan_A | Z3: Feb_A | AA3: Mar_A | AB3: Apr_P | AC3: May_P | AD3: Jun_P | AE3: Jul_P | AF3: Aug_P | AG3: Sep_P | AH3: Oct_P | AI3: Nov_P | AJ3: Dec_P | AK3: Jan_P | AL3: Feb_P | AM3: Mar_P | AN3: Apr_I | AO3: May_I | AP3: Jun_I | AQ3: Jul_I | AR3: Aug_I | AS3: Sep_I | AT3: Oct_I | AU3: Nov_I | AV3: Dec_I | AW3: Jan_I | AX3: Feb_I | AY3: Mar_I | AZ3: Apr_I | BA3: May_I | BB3: Jun_I | BC3: Jul_I | BD3: Aug_I | BE3: Sep_I | BF3: Oct_I | BG3: Nov_I | BH3: Dec_I | BI3: Jan_I | BJ3: Feb_I | BK3: Mar_I | BM3: DirectSupCode | BN3: %Salesman
